Workbook

Sheet testdata
A1: Participant ID | B1: Researcher | C1: Lab | D1: Country | E1: Condition | F1: Target word | G1: Time pressure order | H1: target.low1.coder1 | I1: target.low2.coder1 | J1: target.high1.coder1 | K1: target.high2.coder1 | L1: nontarget.low1.coder1 | M1: nontarget.low2.coder1 | N1: nontarget.high1.coder1 | O1: nontarget.high2.coder1 | P1: target.low1.coder2 | Q1: target.low2.coder2 | R1: target.high1.coder2 | S1: target.high2.coder2 | T1: nontarget.low1.coder2 | U1: nontarget.low2.coder2 | V1: nontarget.high1.coder2 | W1: nontarget.high2.coder2 | X1: target.low1.final | Y1: target.low2.final | Z1: target.high1.final | AA1: target.high2.final | AB1: nontarget.low1.final | AC1: nontarget.low2.final | AD1: nontarget.high1.final | AE1: nontarget.high2.final | AF1: mean.target.low | AG1: mean.target.high | AH1: mean.nontarget.low | AI1: mean.nontarget.high | AJ1: probe.coder1 | AK1: probe.coder2 | AL1: probe.final | AM1: MC | AN1: age | AO1: gender | AP1: Compliance
A2: 1 | B2: Cleo Yusainy | C2: Brawijaya University | D2: Indonesia | E2: 2 | F2: 3 | G2: 1 | H2: 0 | I2: 1 | J2: 0 | K2: 0 | L2: 0 | M2: 0 | N2: 1 | O2: 0 | P2: 0 | Q2: 1 | R2: 0 | S2: 0 | T2: 0 | U2: 0 | V2: 0 | W2: 1 | X2: 0 | Y2: 1 | Z2: 0 | AA2: 0 | AB2: 0 | AC2: 0 | AD2: 1 | AE2: 0 | AF2: =AVERAGE(X2:Y2) -> 0.5 | AG2: =AVERAGE(Z2:AA2) -> 0 | AH2: =AVERAGE(AB2:AC2) -> 0 | AI2: =AVERAGE(AD2:AE2) -> 0.5 | AJ2: 0 | AK2: 0 | AL2: 0 | AM2: 1 | AN2: 20 | AO2: 1 | AP2: 1
A3: 3 | B3: Cleo Yusainy | C3: Brawijaya University | D3: Indonesia | E3: 2 | F3: 2 | G3: 1 | H3: 0 | I3: 0 | J3: 1 | K3: 0 | L3: 1 | M3: 1 | N3: 1 | O3: 0 | P3: 0 | Q3: 0 | R3: 0 | S3: 1 | T3: 1 | U3: 1 | V3: 0 | W3: 1 | X3: 0 | Y3: 0 | Z3: 1 | AA3: 0 | AB3: 1 | AC3: 1 | AD3: 1 | AE3: 0 | AF3: =AVERAGE(X3:Y3) -> 0 | AG3: =AVERAGE(Z3:AA3) -> 0.5 | AH3: =AVERAGE(AB3:AC3) -> 1 | AI3: =AVERAGE(AD3:AE3) -> 0.5 | AJ3: 0 | AK3: 0 | AL3: 0 | AM3: 1 | AN3: 18 | AO3: 1 | AP3: 1
A4: 4 | B4: Cleo Yusainy | C4: Brawijaya University | D4: Indonesia | E4: 1 | F4: 2 | G4: 2 | H4: 0 | I4: 0 | J4: 0 | K4: 0 | L4: 0 | M4: 0 | N4: 0 | O4: 1 | P4: 0 | Q4: 0 | R4: 0 | S4: 0 | T4: 0 | U4: 0 | V4: 0 | W4: 1 | X4: 0 | Y4: 0 | Z4: 0 | AA4: 0 | AB4: 0 | AC4: 0 | AD4: 0 | AE4: 1 | AF4: =AVERAGE(X4:Y4) -> 0 | AG4: =AVERAGE(Z4:AA4) -> 0 | AH4: =AVERAGE(AB4:AC4) -> 0 | AI4: =AVERAGE(AD4:AE4) -> 0.5 | AJ4: 0 | AK4: 0 | AL4: 0 | AM4: 2 | AN4: 18 | AO4: 2 | AP4: 1
A5: 5 | B5: Cleo Yusainy | C5: Brawijaya University | D5: Indonesia | E5: 2 | F5: 2 | G5: 2 | H5: 0 | I5: 0 | J5: 1 | K5: 0 | L5: 1 | M5: 0 | N5: 0 | O5: 1 | P5: 0 | Q5: 0 | R5: 1 | S5: 0 | T5: 1 | U5: 0 | V5: 0 | W5: 1 | X5: 0 | Y5: 0 | Z5: 1 | AA5: 0 | AB5: 1 | AC5: 0 | AD5: 0 | AE5: 1 | AF5: =AVERAGE(X5:Y5) -> 0 | AG5: =AVERAGE(Z5:AA5) -> 0.5 | AH5: =AVERAGE(AB5:AC5) -> 0.5 | AI5: =AVERAGE(AD5:AE5) -> 0.5 | AJ5: 0 | AK5: 0 | AL5: 0 | AM5: 1 | AN5: 18 | AO5: 1 | AP5: 1
A6: 7 | B6: Cleo Yusainy | C6: Brawijaya University | D6: Indonesia | E6: 1 | F6: 1 | G6: 2 | H6: 0 | I6: 0 | J6: 0 | K6: 0 | L6: 1 | M6: 0 | N6: 0 | O6: 0 | P6: 0 | Q6: 0 | R6: 1 | S6: 0 | T6: 1 | U6: 0 | V6: 0 | W6: 0 | X6: 0 | Y6: 0 | Z6: 0 | AA6: 0 | AB6: 1 | AC6: 0 | AD6: 0 | AE6: 0 | AF6: =AVERAGE(X6:Y6) -> 0 | AG6: =AVERAGE(Z6:AA6) -> 0 | AH6: =AVERAGE(AB6:AC6) -> 0.5 | AI6: =AVERAGE(AD6:AE6) -> 0 | AJ6: 0 | AK6: 0 | AL6: 0 | AM6: 2 | AN6: 18 | AO6: 1 | AP6: 1
A7: 8 | B7: Cleo Yusainy | C7: Brawijaya University | D7: Indonesia | E7: 2 | F7: 1 | G7: 2 | H7: 0 | I7: 0 | J7: 0 | K7: 0 | L7: 0 | M7: 1 | N7: 1 | O7: 0 | P7: 1 | Q7: 0 | R7: 0 | S7: 0 | T7: 0 | U7: 0 | V7: 1 | W7: 1 | X7: 0 | Y7: 0 | Z7: 0 | AA7: 0 | AB7: 0 | AC7: 1 | AD7: 1 | AE7: 0 | AF7: =AVERAGE(X7:Y7) -> 0 | AG7: =AVERAGE(Z7:AA7) -> 0 | AH7: =AVERAGE(AB7:AC7) -> 0.5 | AI7: =AVERAGE(AD7:AE7) -> 0.5 | AJ7: 0 | AK7: 0 | AL7: 0 | AM7: 2 | AN7: 18 | AO7: 1 | AP7: 2
A8: 9 | B8: Cleo Yusainy | C8: Brawijaya University | D8: Indonesia | E8: 1 | F8: 4 | G8: 1 | H8: 0 | I8: 0 | J8: 0 | K8: 0 | L8: 0 | M8: 0 | N8: 0 | O8: 0 | P8: 0 | Q8: 0 | R8: 0 | S8: 0 | T8: 0 | U8: 0 | V8: 0 | W8: 0 | X8: 0 | Y8: 0 | Z8: 0 | AA8: 0 | AB8: 0 | AC8: 0 | AD8: 0 | AE8: 0 | AF8: =AVERAGE(X8:Y8) -> 0 | AG8: =AVERAGE(Z8:AA8) -> 0 | AH8: =AVERAGE(AB8:AC8) -> 0 | AI8: =AVERAGE(AD8:AE8) -> 0 | AJ8: 0 | AK8: 0 | AL8: 0 | AM8: 1 | AN8: 18 | AO8: 1 | AP8: 2
A9: 10 | B9: Cleo Yusainy | C9: Brawijaya University | D9: Indonesia | E9: 1 | F9: 3 | G9: 1 | H9: 0 | I9: 0 | J9: 0 | K9: 0 | L9: 1 | M9: 0 | N9: 1 | O9: 0 | P9: 0 | Q9: 0 | R9: 0 | S9: 0 | T9: 1 | U9: 0 | V9: 1 | W9: 0 | X9: 0 | Y9: 0 | Z9: 0 | AA9: 0 | AB9: 1 | AC9: 0 | AD9: 1 | AE9: 0 | AF9: =AVERAGE(X9:Y9) -> 0 | AG9: =AVERAGE(Z9:AA9) -> 0 | AH9: =AVERAGE(AB9:AC9) -> 0.5 | AI9: =AVERAGE(AD9:AE9) -> 0.5 | AJ9: 0 | AK9: 0 | AL9: 0 | AM9: 2 | AN9: 18 | AO9: 1 | AP9: 1
A10: 11 | B10: Cleo Yusainy | C10: Brawijaya University | D10: Indonesia | E10: 2 | F10: 4 | G10: 2 | H10: 0 | I10: 0 | J10: 0 | K10: 1 | L10: 0 | M10: 1 | N10: 0 | O10: 0 | P10: 0 | Q10: 0 | R10: 1 | S10: 0 | T10: 1 | U10: 0 | V10: 0 | W10: 0 | X10: 0 | Y10: 0 | Z10: 0 | AA10: 1 | AB10: 0 | AC10: 1 | AD10: 0 | AE10: 0 | AF10: =AVERAGE(X10:Y10) -> 0 | AG10: =AVERAGE(Z10:AA10) -> 0.5 | AH10: =AVERAGE(AB10:AC10) -> 0.5 | AI10: =AVERAGE(AD10:AE10) -> 0 | AJ10: 0 | AK10: 0 | AL10: 0 | AM10: 1 | AN10: 19 | AO10: 1 | AP10: 1
A11: 12 | B11: Cleo Yusainy | C11: Brawijaya University | D11: Indonesia | E11: 1 | F11: 4 | G11: 2 | H11: 0 | I11: 0 | J11: 0 | K11: 0 | L11: 0 | M11: 0 | N11: 0 | O11: 1 | P11: 0 | Q11: 0 | R11: 0 | S11: 0 | T11: 0 | U11: 0 | V11: 0 | W11: 1 | X11: 0 | Y11: 0 | Z11: 0 | AA11: 0 | AB11: 0 | AC11: 0 | AD11: 0 | AE11: 1 | AF11: =AVERAGE(X11:Y11) -> 0 | AG11: =AVERAGE(Z11:AA11) -> 0 | AH11: =AVERAGE(AB11:AC11) -> 0 | AI11: =AVERAGE(AD11:AE11) -> 0.5 | AJ11: 0 | AK11: 0 | AL11: 0 | AM11: 1 | AN11: 18 | AO11: 1 | AP11: 2
A12: 14 | B12: Cleo Yusainy | C12: Brawijaya University | D12: Indonesia | E12: 2 | F12: 4 | G12: 1 | H12: 0 | I12: 0 | J12: 1 | K12: 0 | L12: 0 | M12: 1 | N12: 1 | O12: 0 | P12: 1 | Q12: 0 | R12: 0 | S12: 0 | T12: 0 | U12: 0 | V12: 0 | W12: 0 | X12: 0 | Y12: 0 | Z12: 1 | AA12: 0 | AB12: 0 | AC12: 1 | AD12: 1 | AE12: 0 | AF12: =AVERAGE(X12:Y12) -> 0 | AG12: =AVERAGE(Z12:AA12) -> 0.5 | AH12: =AVERAGE(AB12:AC12) -> 0.5 | AI12: =AVERAGE(AD12:AE12) -> 0.5 | AJ12: 0 | AK12: 0 | AL12: 0 | AM12: 1 | AN12: 17 | AO12: 1 | AP12: 1
A13: 17 | B13: Cleo Yusainy | C13: Brawijaya University | D13: Indonesia | E13: 1 | F13: 1 | G13: 1 | H13: 0 | I13: 0 | J13: 0 | K13: 0 | L13: 0 | M13: 0 | N13: 0 | O13: 0 | P13: 1 | Q13: 0 | R13: 0 | S13: 0 | T13: 0 | U13: 0 | V13: 0 | W13: 0 | X13: 0 | Y13: 0 | Z13: 0 | AA13: 0 | AB13: 0 | AC13: 0 | AD13: 0 | AE13: 0 | AF13: =AVERAGE(X13:Y13) -> 0 | AG13: =AVERAGE(Z13:AA13) -> 0 | AH13: =AVERAGE(AB13:AC13) -> 0 | AI13: =AVERAGE(AD13:AE13) -> 0 | AJ13: 0 | AK13: 0 | AL13: 0 | AM13: 1 | AN13: 18 | AO13: 1 | AP13: 2
... A123: 185 | B123: Cleo Yusainy | C123: Brawijaya University | D123: Indonesia | E123: 2 | F123: 4 | G123: 2 | H123: 1 | I123: 0 | J123: 0 | K123: 0 | L123: 1 | M123: 0 | N123: 0 | O123: 0 | P123: 0 | Q123: 1 | R123: 0 | S123: 0 | T123: 0 | U123: 1 | V123: 0 | W123: 0 | X123: 0 | Y123: 1 | Z123: 0 | AA123: 0 | AB123: 0 | AC123: 1 | AD123: 0 | AE123: 0 | AF123: =AVERAGE(X123:Y123) -> 0.5 | AG123: =AVERAGE(Z123:AA123) -> 0 | AH123: =AVERAGE(AB123:AC123) -> 0.5 | AI123: =AVERAGE(AD123:AE123) -> 0 | AJ123: 0 | AK123: 0 | AL123: 0 | AM123: 1 | AN123: 19 | AO123: 1 | AP123: 1
A124: 186 | B124: Cleo Yusainy | C124: Brawijaya University | D124: Indonesia | E124: 1 | F124: 3 | G124: 1 | H124: NA | I124: NA | J124: NA | K124: NA | L124: NA | M124: NA | N124: NA | O124: NA | P124: NA | Q124: NA | R124: NA | S124: NA | T124: NA | U124: NA | V124: NA | W124: NA | X124: NA | Y124: NA | Z124: NA | AA124: NA | AB124: NA | AC124: NA | AD124: NA | AE124: NA | AF124: NA | AG124: NA | AH124: NA | AI124: NA | AJ124: 0 | AK124: 0 | AL124: 0 | AM124: 2 | AN124: 18 | AO124: 1 | AP124: 1
A125: 188 | B125: Cleo Yusainy | C125: Brawijaya University | D125: Indonesia | E125: 1 | F125: 3 | G125: 2 | H125: 0 | I125: 0 | J125: 0 | K125: 0 | L125: 1 | M125: 0 | N125: 0 | O125: 1 | P125: 0 | Q125: 0 | R125: 0 | S125: 0 | T125: 1 | U125: 0 | V125: 0 | W125: 1 | X125: 0 | Y125: 0 | Z125: 0 | AA125: 0 | AB125: 1 | AC125: 0 | AD125: 0 | AE125: 1 | AF125: =AVERAGE(X125:Y125) -> 0 | AG125: =AVERAGE(Z125:AA125) -> 0 | AH125: =AVERAGE(AB125:AC125) -> 0.5 | AI125: =AVERAGE(AD125:AE125) -> 0.5 | AJ125: 0 | AK125: 0 | AL125: 0 | AM125: 1 | AN125: 17 | AO125: 1 | AP125: 2
A126: 191 | B126: Cleo Yusainy | C126: Brawijaya University | D126: Indonesia | E126: 1 | F126: 4 | G126: 1 | H126: 0 | I126: 0 | J126: 1 | K126: 0 | L126: 0 | M126: 0 | N126: 0 | O126: 0 | P126: 0 | Q126: 0 | R126: 1 | S126: 0 | T126: 0 | U126: 0 | V126: 0 | W126: 0 | X126: 0 | Y126: 0 | Z126: 1 | AA126: 0 | AB126: 0 | AC126: 0 | AD126: 0 | AE126: 0 | AF126: =AVERAGE(X126:Y126) -> 0 | AG126: =AVERAGE(Z126:AA126) -> 0.5 | AH126: =AVERAGE(AB126:AC126) -> 0 | AI126: =AVERAGE(AD126:AE126) -> 0 | AJ126: 0 | AK126: 0 | AL126: 0 | AM126: 2 | AN126: 18 | AO126: 1 | AP126: 1
A127: 193 | B127: Cleo Yusainy | C127: Brawijaya University | D127: Indonesia | E127: 1 | F127: 1 | G127: 2 | H127: 0 | I127: 0 | J127: 0 | K127: 1 | L127: 0 | M127: 0 | N127: 0 | O127: 0 | P127: 0 | Q127: 0 | R127: 0 | S127: 1 | T127: 0 | U127: 0 | V127: 0 | W127: 0 | X127: 0 | Y127: 0 | Z127: 0 | AA127: 1 | AB127: 0 | AC127: 0 | AD127: 0 | AE127: 0 | AF127: =AVERAGE(X127:Y127) -> 0 | AG127: =AVERAGE(Z127:AA127) -> 0.5 | AH127: =AVERAGE(AB127:AC127) -> 0 | AI127: =AVERAGE(AD127:AE127) -> 0 | AJ127: 0 | AK127: 0 | AL127: 0 | AM127: 2 | AN127: 19 | AO127: 1 | AP127: 1
A128: 194 | B128: Cleo Yusainy | C128: Brawijaya University | D128: Indonesia | E128: 1 | F128: 4 | G128: 1 | H128: 0 | I128: 0 | J128: 0 | K128: 1 | L128: 0 | M128: 0 | N128: 0 | O128: 0 | P128: 0 | Q128: 0 | R128: 0 | S128: 0 | T128: 0 | U128: 0 | V128: 0 | W128: 0 | X128: 0 | Y128: 0 | Z128: 0 | AA128: 0 | AB128: 0 | AC128: 0 | AD128: 0 | AE128: 0 | AF128: =AVERAGE(X128:Y128) -> 0 | AG128: =AVERAGE(Z128:AA128) -> 0 | AH128: =AVERAGE(AB128:AC128) -> 0 | AI128: =AVERAGE(AD128:AE128) -> 0 | AJ128: 0 | AK128: 0 | AL128: 0 | AM128: 2 | AN128: 18 | AO128: 2 | AP128: 1
A129: 197 | B129: Cleo Yusainy | C129: Brawijaya University | D129: Indonesia | E129: 2 | F129: 1 | G129: 1 | H129: 0 | I129: 1 | J129: 1 | K129: 1 | L129: 1 | M129: 1 | N129: 0 | O129: 1 | P129: 0 | Q129: 1 | R129: 1 | S129: 1 | T129: 1 | U129: 0 | V129: 0 | W129: 1 | X129: 0 | Y129: 1 | Z129: 1 | AA129: 1 | AB129: 1 | AC129: 0 | AD129: 0 | AE129: 1 | AF129: =AVERAGE(X129:Y129) -> 0.5 | AG129: =AVERAGE(Z129:AA129) -> 1 | AH129: =AVERAGE(AB129:AC129) -> 0.5 | AI129: =AVERAGE(AD129:AE129) -> 0.5 | AJ129: 0 | AK129: 0 | AL129: 0 | AM129: 1 | AN129: 18 | AO129: 1 | AP129: 1
A130: 198 | B130: Cleo Yusainy | C130: Brawijaya University | D130: Indonesia | E130: 2 | F130: 3 | G130: 2 | H130: 0 | I130: 0 | J130: 0 | K130: 0 | L130: 1 | M130: 0 | N130: 0 | O130: 0 | P130: 0 | Q130: 0 | R130: 0 | S130: 0 | T130: 1 | U130: 0 | V130: 0 | W130: 0 | X130: 0 | Y130: 0 | Z130: 0 | AA130: 0 | AB130: 1 | AC130: 0 | AD130: 0 | AE130: 0 | AF130: =AVERAGE(X130:Y130) -> 0 | AG130: =AVERAGE(Z130:AA130) -> 0 | AH130: =AVERAGE(AB130:AC130) -> 0.5 | AI130: =AVERAGE(AD130:AE130) -> 0 | AJ130: 0 | AK130: 0 | AL130: 0 | AM130: 1 | AN130: 17 | AO130: 1 | AP130: 1
A131: 202 | B131: Cleo Yusainy | C131: Brawijaya University | D131: Indonesia | E131: 2 | F131: 4 | G131: 2 | H131: 0 | I131: 0 | J131: 0 | K131: 1 | L131: 0 | M131: 1 | N131: 0 | O131: 0 | P131: 0 | Q131: 0 | R131: 0 | S131: 1 | T131: 0 | U131: 1 | V131: 0 | W131: 0 | X131: 0 | Y131: 0 | Z131: 0 | AA131: 1 | AB131: 0 | AC131: 1 | AD131: 0 | AE131: 0 | AF131: =AVERAGE(X131:Y131) -> 0 | AG131: =AVERAGE(Z131:AA131) -> 0.5 | AH131: =AVERAGE(AB131:AC131) -> 0.5 | AI131: =AVERAGE(AD131:AE131) -> 0 | AJ131: 0 | AK131: 0 | AL131: 0 | AM131: 1 | AN131: 18 | AO131: 1 | AP131: 1
A132: 203 | B132: Cleo Yusainy | C132: Brawijaya University | D132: Indonesia | E132: 1 | F132: 2 | G132: 1 | H132: 0 | I132: 0 | J132: 0 | K132: 0 | L132: 0 | M132: 1 | N132: 0 | O132: 0 | P132: 0 | Q132: 0 | R132: 0 | S132: 0 | T132: 0 | U132: 0 | V132: 0 | W132: 0 | X132: 0 | Y132: 0 | Z132: 0 | AA132: 0 | AB132: 0 | AC132: 0 | AD132: 0 | AE132: 0 | AF132: =AVERAGE(X132:Y132) -> 0 | AG132: =AVERAGE(Z132:AA132) -> 0 | AH132: =AVERAGE(AB132:AC132) -> 0 | AI132: =AVERAGE(AD132:AE132) -> 0 | AJ132: 0 | AK132: 0 | AL132: 0 | AM132: 1 | AN132: 16 | AO132: 1 | AP132: 2
A133: 204 | B133: Cleo Yusainy | C133: Brawijaya University | D133: Indonesia | E133: 2 | F133: 3 | G133: 1 | H133: 0 | I133: 0 | J133: 0 | K133: 0 | L133: 1 | M133: 1 | N133: 1 | O133: 0 | P133: 0 | Q133: 0 | R133: 0 | S133: 0 | T133: 1 | U133: 1 | V133: 1 | W133: 0 | X133: 0 | Y133: 0 | Z133: 0 | AA133: 0 | AB133: 1 | AC133: 1 | AD133: 1 | AE133: 0 | AF133: =AVERAGE(X133:Y133) -> 0 | AG133: =AVERAGE(Z133:AA133) -> 0 | AH133: =AVERAGE(AB133:AC133) -> 1 | AI133: =AVERAGE(AD133:AE133) -> 0.5 | AJ133: 0 | AK133: 0 | AL133: 0 | AM133: 1 | AN133: 18 | AO133: 1 | AP133: 1
A134: 206 | B134: Cleo Yusainy | C134: Brawijaya University | D134: Indonesia | E134: 1 | F134: 3 | G134: 1 | H134: 0 | I134: 0 | J134: 0 | K134: 0 | L134: 1 | M134: 1 | N134: 1 | O134: 0 | P134: 0 | Q134: 0 | R134: 0 | S134: 0 | T134: 0 | U134: 1 | V134: 1 | W134: 0 | X134: 0 | Y134: 0 | Z134: 0 | AA134: 0 | AB134: 0 | AC134: 1 | AD134: 1 | AE134: 0 | AF134: =AVERAGE(X134:Y134) -> 0 | AG134: =AVERAGE(Z134:AA134) -> 0 | AH134: =AVERAGE(AB134:AC134) -> 0.5 | AI134: =AVERAGE(AD134:AE134) -> 0.5 | AJ134: 0 | AK134: 0 | AL134: 0 | AM134: 2 | AN134: 17 | AO134: 1 | AP134: 1
A135: 207 | B135: Cleo Yusainy | C135: Brawijaya University | D135: Indonesia | E135: 1 | F135: 2 | G135: 2 | H135: 0 | I135: 0 | J135: 0 | K135: 0 | L135: 0 | M135: 1 | N135: 0 | O135: 1 | P135: 0 | Q135: 0 | R135: 0 | S135: 0 | T135: 0 | U135: 1 | V135: 0 | W135: 1 | X135: 0 | Y135: 0 | Z135: 0 | AA135: 0 | AB135: 0 | AC135: 1 | AD135: 0 | AE135: 1 | AF135: =AVERAGE(X135:Y135) -> 0 | AG135: =AVERAGE(Z135:AA135) -> 0 | AH135: =AVERAGE(AB135:AC135) -> 0.5 | AI135: =AVERAGE(AD135:AE135) -> 0.5 | AJ135: 0 | AK135: 0 | AL135: 0 | AM135: 2 | AN135: 17 | AO135: 1 | AP135: 1
A136: 208 | B136: Cleo Yusainy | C136: Brawijaya University | D136: Indonesia | E136: 1 | F136: 4 | G136: 2 | H136: 0 | I136: 0 | J136: 0 | K136: 0 | L136: 0 | M136: 0 | N136: 0 | O136: 0 | P136: 0 | Q136: 0 | R136: 0 | S136: 0 | T136: 0 | U136: 0 | V136: 0 | W136: 0 | X136: 0 | Y136: 0 | Z136: 0 | AA136: 0 | AB136: 0 | AC136: 0 | AD136: 0 | AE136: 0 | AF136: =AVERAGE(X136:Y136) -> 0 | AG136: =AVERAGE(Z136:AA136) -> 0 | AH136: =AVERAGE(AB136:AC136) -> 0 | AI136: =AVERAGE(AD136:AE136) -> 0 | AJ136: 0 | AK136: 0 | AL136: 0 | AM136: 2 | AN136: 18 | AO136: 1 | AP136: 1
... A146: 222 | B146: Cleo Yusainy | C146: Brawijaya University | D146: Indonesia | E146: 2 | F146: 3 | G146: 1 | H146: 0 | I146: 0 | J146: 0 | K146: 0 | L146: 0 | M146: 0 | N146: 0 | O146: 0 | P146: 0 | Q146: 0 | R146: 0 | S146: 0 | T146: 0 | U146: 0 | V146: 0 | W146: 0 | X146: 0 | Y146: 0 | Z146: 0 | AA146: 0 | AB146: 0 | AC146: 0 | AD146: 0 | AE146: 0 | AF146: =AVERAGE(X146:Y146) -> 0 | AG146: =AVERAGE(Z146:AA146) -> 0 | AH146: =AVERAGE(AB146:AC146) -> 0 | AI146: =AVERAGE(AD146:AE146) -> 0 | AJ146: 0 | AK146: 0 | AL146: 0 | AM146: 1 | AN146: 18 | AO146: 2 | AP146: 1
A147: 223 | B147: Cleo Yusainy | C147: Brawijaya University | D147: Indonesia | E147: 1 | F147: 3 | G147: 2 | H147: NA | I147: NA | J147: NA | K147: NA | L147: NA | M147: NA | N147: NA | O147: NA | P147: NA | Q147: NA | R147: NA | S147: NA | T147: NA | U147: NA | V147: NA | W147: NA | X147: NA | Y147: NA | Z147: NA | AA147: NA | AB147: NA | AC147: NA | AD147: NA | AE147: NA | AF147: NA | AG147: NA | AH147: NA | AI147: NA | AJ147: 0 | AK147: 0 | AL147: 0 | AM147: 2 | AN147: 18 | AO147: 2 | AP147: 1
A148: 224 | B148: Cleo Yusainy | C148: Brawijaya University | D148: Indonesia | E148: 2 | F148: 3 | G148: 2 | H148: 0 | I148: 0 | J148: 0 | K148: 1 | L148: 0 | M148: 1 | N148: 0 | O148: 0 | P148: 0 | Q148: 0 | R148: 0 | S148: 1 | T148: 0 | U148: 1 | V148: 0 | W148: 0 | X148: 0 | Y148: 0 | Z148: 0 | AA148: 1 | AB148: 0 | AC148: 1 | AD148: 0 | AE148: 0 | AF148: =AVERAGE(X148:Y148) -> 0 | AG148: =AVERAGE(Z148:AA148) -> 0.5 | AH148: =AVERAGE(AB148:AC148) -> 0.5 | AI148: =AVERAGE(AD148:AE148) -> 0 | AJ148: 0 | AK148: 0 | AL148: 0 | AM148: 1 | AN148: 18 | AO148: 1 | AP148: 1
A149: 226 | B149: Cleo Yusainy | C149: Brawijaya University | D149: Indonesia | E149: 1 | F149: 2 | G149: 1 | H149: 0 | I149: 0 | J149: 0 | K149: 0 | L149: 0 | M149: 1 | N149: 1 | O149: 0 | P149: 0 | Q149: 0 | R149: 0 | S149: 0 | T149: 0 | U149: 1 | V149: 1 | W149: 0 | X149: 0 | Y149: 0 | Z149: 0 | AA149: 0 | AB149: 0 | AC149: 1 | AD149: 1 | AE149: 0 | AF149: =AVERAGE(X149:Y149) -> 0 | AG149: =AVERAGE(Z149:AA149) -> 0 | AH149: =AVERAGE(AB149:AC149) -> 0.5 | AI149: =AVERAGE(AD149:AE149) -> 0.5 | AJ149: 0 | AK149: 0 | AL149: 0 | AM149: 2 | AN149: 17 | AO149: 1 | AP149: 1
A150: 228 | B150: Cleo Yusainy | C150: Brawijaya University | D150: Indonesia | E150: 2 | F150: 4 | G150: 1 | H150: 0 | I150: 1 | J150: 1 | K150: 0 | L150: 1 | M150: 1 | N150: 0 | O150: 0 | P150: 0 | Q150: 1 | R150: 1 | S150: 0 | T150: 1 | U150: 1 | V150: 0 | W150: 0 | X150: 0 | Y150: 1 | Z150: 1 | AA150: 0 | AB150: 1 | AC150: 1 | AD150: 0 | AE150: 0 | AF150: =AVERAGE(X150:Y150) -> 0.5 | AG150: =AVERAGE(Z150:AA150) -> 0.5 | AH150: =AVERAGE(AB150:AC150) -> 1 | AI150: =AVERAGE(AD150:AE150) -> 0 | AJ150: 0 | AK150: 0 | AL150: 0 | AM150: 1 | AN150: 18 | AO150: 1 | AP150: 1
A151: 233 | B151: Cleo Yusainy | C151: Brawijaya University | D151: Indonesia | E151: 2 | F151: 1 | G151: 1 | H151: 0 | I151: 1 | J151: 1 | K151: 0 | L151: 0 | M151: 0 | N151: 1 | O151: 0 | P151: 1 | Q151: 0 | R151: 0 | S151: 1 | T151: 0 | U151: 0 | V151: 1 | W151: 0 | X151: 1 | Y151: 0 | Z151: 0 | AA151: 1 | AB151: 0 | AC151: 0 | AD151: 1 | AE151: 0 | AF151: =AVERAGE(X151:Y151) -> 0.5 | AG151: =AVERAGE(Z151:AA151) -> 0.5 | AH151: =AVERAGE(AB151:AC151) -> 0 | AI151: =AVERAGE(AD151:AE151) -> 0.5 | AJ151: 0 | AK151: 0 | AL151: 0 | AM151: 1 | AN151: 18 | AO151: 1 | AP151: 1
A152: 234 | B152: Cleo Yusainy | C152: Brawijaya University | D152: Indonesia | E152: 1 | F152: 4 | G152: 2 | H152: 0 | I152: 0 | J152: 0 | K152: 0 | L152: 0 | M152: 1 | N152: 0 | O152: 0 | P152: 0 | Q152: 0 | R152: 0 | S152: 0 | T152: 0 | U152: 1 | V152: 0 | W152: 0 | X152: 0 | Y152: 0 | Z152: 0 | AA152: 0 | AB152: 0 | AC152: 1 | AD152: 0 | AE152: 0 | AF152: =AVERAGE(X152:Y152) -> 0 | AG152: =AVERAGE(Z152:AA152) -> 0 | AH152: =AVERAGE(AB152:AC152) -> 0.5 | AI152: =AVERAGE(AD152:AE152) -> 0 | AJ152: 0 | AK152: 0 | AL152: 0 | AM152: 2 | AN152: 20 | AO152: 1 | AP152: 1
A153: 235 | B153: Cleo Yusainy | C153: Brawijaya University | D153: Indonesia | E153: 2 | F153: 1 | G153: 2 | H153: 0 | I153: 0 | J153: 0 | K153: 0 | L153: 0 | M153: 0 | N153: 0 | O153: 0 | P153: 0 | Q153: 0 | R153: 0 | S153: 0 | T153: 0 | U153: 0 | V153: 0 | W153: 0 | X153: 0 | Y153: 0 | Z153: 0 | AA153: 0 | AB153: 0 | AC153: 0 | AD153: 0 | AE153: 0 | AF153: =AVERAGE(X153:Y153) -> 0 | AG153: =AVERAGE(Z153:AA153) -> 0 | AH153: =AVERAGE(AB153:AC153) -> 0 | AI153: =AVERAGE(AD153:AE153) -> 0 | AJ153: 0 | AK153: 0 | AL153: 0 | AM153: 1 | AN153: 21 | AO153: 2 | AP153: 1
A154: 236 | B154: Cleo Yusainy | C154: Brawijaya University | D154: Indonesia | E154: 2 | F154: 4 | G154: 2 | H154: 1 | I154: 1 | J154: 0 | K154: 0 | L154: 0 | M154: 0 | N154: 0 | O154: 0 | P154: 0 | Q154: 0 | R154: 0 | S154: 0 | T154: 0 | U154: 0 | V154: 0 | W154: 0 | X154: 0 | Y154: 0 | Z154: 0 | AA154: 0 | AB154: 0 | AC154: 0 | AD154: 0 | AE154: 0 | AF154: =AVERAGE(X154:Y154) -> 0 | AG154: =AVERAGE(Z154:AA154) -> 0 | AH154: =AVERAGE(AB154:AC154) -> 0 | AI154: =AVERAGE(AD154:AE154) -> 0 | AJ154: 0 | AK154: 0 | AL154: 0 | AM154: 1 | AN154: 18 | AO154: 1 | AP154: 1
A155: 237 | B155: Cleo Yusainy | C155: Brawijaya University | D155: Indonesia | E155: 1 | F155: 1 | G155: 2 | H155: 0 | I155: 0 | J155: 0 | K155: 0 | L155: 0 | M155: 1 | N155: 0 | O155: 0 | P155: 0 | Q155: 0 | R155: 0 | S155: 0 | T155: 0 | U155: 1 | V155: 0 | W155: 0 | X155: 0 | Y155: 0 | Z155: 0 | AA155: 0 | AB155: 0 | AC155: 1 | AD155: 0 | AE155: 0 | AF155: =AVERAGE(X155:Y155) -> 0 | AG155: =AVERAGE(Z155:AA155) -> 0 | AH155: =AVERAGE(AB155:AC155) -> 0.5 | AI155: =AVERAGE(AD155:AE155) -> 0 | AJ155: 0 | AK155: 0 | AL155: 0 | AM155: 1 | AN155: 19 | AO155: 1 | AP155: 2
A156: 238 | B156: Cleo Yusainy | C156: Brawijaya University | D156: Indonesia | E156: 1 | F156: 1 | G156: 1 | H156: 0 | I156: 0 | J156: 0 | K156: 0 | L156: 0 | M156: 0 | N156: 0 | O156: 0 | P156: 0 | Q156: 0 | R156: 0 | S156: 0 | T156: 0 | U156: 0 | V156: 0 | W156: 0 | X156: 0 | Y156: 0 | Z156: 0 | AA156: 0 | AB156: 0 | AC156: 0 | AD156: 0 | AE156: 0 | AF156: =AVERAGE(X156:Y156) -> 0 | AG156: =AVERAGE(Z156:AA156) -> 0 | AH156: =AVERAGE(AB156:AC156) -> 0 | AI156: =AVERAGE(AD156:AE156) -> 0 | AJ156: 0 | AK156: 0 | AL156: 0 | AM156: 2 | AN156: 19 | AO156: 2 | AP156: 1
A157: 239 | B157: Cleo Yusainy | C157: Brawijaya University | D157: Indonesia | E157: 1 | F157: 2 | G157: 2 | H157: NA | I157: NA | J157: NA | K157: NA | L157: NA | M157: NA | N157: NA | O157: NA | P157: NA | Q157: NA | R157: NA | S157: NA | T157: NA | U157: NA | V157: NA | W157: NA | X157: NA | Y157: NA | Z157: NA | AA157: NA | AB157: NA | AC157: NA | AD157: NA | AE157: NA | AF157: NA | AG157: NA | AH157: NA | AI157: NA | AJ157: 0 | AK157: 0 | AL157: 0 | AM157: 2 | AN157: 19 | AO157: 2 | AP157: 1
A158: 240 | B158: Cleo Yusainy | C158: Brawijaya University | D158: Indonesia | E158: 1 | F158: 3 | G158: 1 | H158: 0 | I158: 0 | J158: 0 | K158: 0 | L158: 0 | M158: 0 | N158: 1 | O158: 0 | P158: 0 | Q158: 0 | R158: 0 | S158: 0 | T158: 0 | U158: 0 | V158: 1 | W158: 0 | X158: 0 | Y158: 0 | Z158: 0 | AA158: 0 | AB158: 0 | AC158: 0 | AD158: 1 | AE158: 0 | AF158: =AVERAGE(X158:Y158) -> 0 | AG158: =AVERAGE(Z158:AA158) -> 0 | AH158: =AVERAGE(AB158:AC158) -> 0 | AI158: =AVERAGE(AD158:AE158) -> 0.5 | AJ158: 0 | AK158: 0 | AL158: 0 | AM158: 2 | AN158: 18 | AO158: 1 | AP158: 1
...

Sheet case notes
A1: KQ
A2: Blanks replaced with NA
A3: - replaced with NA

Sheet summarystats
A1: Correct responses
B2: Concentration | C2: Suppression
A3: High time pressure | B3: =AVERAGEIF(testdata!$E$2:$E$14, "Concentration", testdata!AG2:AG14) -> #DIV/0! | C3: =AVERAGEIF(testdata!$E$2:$E$14, "Suppression", testdata!AG2:AG14) -> #DIV/0!
A4: Low time pressure | B4: =AVERAGEIF(testdata!$E$2:$E$14, "Concentration", testdata!AF2:AF14) -> #DIV/0! | C4: =AVERAGEIF(testdata!$E$2:$E$14, "Suppression", testdata!AF2:AF14) -> #DIV/0!
A6: RT responses
B7: Concentration | C7: Suppression
A8: High time pressure | B8: =AVERAGEIF(testdata!$E$2:$E$14, "Concentration", testdata!#REF!) -> #REF! | C8: =AVERAGEIF(testdata!$E$2:$E$14, "Suppression", testdata!#REF!) -> #REF!
A9: Low time pressure | B9: =AVERAGEIF(testdata!$E$2:$E$14, "Concentration", testdata!#REF!) -> #REF! | C9: =AVERAGEIF(testdata!$E$2:$E$14, "Suppression", testdata!#REF!) -> #REF!
