Workbook

Sheet testdata
A1: Notes: | D1: ParticipantID | E1: Condition | F1: Targetword | G1: A_period.1.coder1 | H1: B_period.1.coder1 | I1: C_period.1.coder1 | J1: A_period.1.coder2 | K1: B_period.1.coder2 | L1: C_period.1.coder2 | M1: A_period.1.final | N1: B_period.1.final | O1: C_period.1.final | P1: sum.of.ABC_period.1.final | Q1: A_period.2.coder1 | R1: B_period.2.coder1 | S1: C_period.2.coder1 | T1: A_period.2.coder2 | U1: B_period.2.coder2 | V1: C_period.2.coder2 | W1: A_period.2.final | X1: B_period.2.final | Y1: C_period.2.final | Z1: sum.ABC_period2.final | AA1: Percentage.round.1 | AB1: Percentage.round.2 | AC1: probe.coder1 | AD1: probe.coder2 | AE1: probe.final | AF1: MC | AG1: age | AH1: gender | AI1: Compliance
A2: Condition (initial suppression = 1, initial concentration = 2) | C2: Example | D2: 1001 | E2: 1 | F2: 1 | G2: 18 | H2: 4 | I2: 8 | J2: 18 | K2: 4 | L2: 8 | M2: 18 | N2: 4 | O2: 8 | P2: =SUM(M2,Q2,N2,O2) -> 44 | Q2: 14 | R2: 15 | S2: 20 | T2: 14 | U2: 15 | V2: 20 | W2: 14 | X2: 15 | Y2: 20 | Z2: =SUM(W2,X2,Y2) -> 49 | AC2: 0 | AD2: 0 | AE2: 0 | AF2: 1 | AG2: 30 | AH2: 1 | AI2: 1
A3: Target word (gorilla = 1, tiger = 2, food = 3, diseases = 4) | D3: 1002 | E3: 1 | F3: 2 | G3: 18 | H3: 16 | I3: 16 | J3: 18 | K3: 16 | L3: 16 | M3: 18 | N3: 16 | O3: 16 | P3: =SUM(M3,Q3,N3,O3) -> 63 | Q3: 13 | R3: 16 | S3: 15 | T3: 13 | U3: 16 | V3: 15 | W3: 13 | X3: 16 | Y3: 15 | Z3: =SUM(W3,X3,Y3) -> 44 | AC3: 0 | AD3: 1 | AE3: 0 | AF3: 1 | AG3: 25 | AH3: 1 | AI3: 1
A4: Participant ID should start from 121 rather than 001 | D4: 1003 | E4: 2 | F4: 3 | G4: 2 | H4: 3 | I4: 19 | J4: 2 | K4: 3 | L4: 19 | M4: 2 | N4: 3 | O4: 19 | P4: =SUM(M4,Q4,N4,O4) -> 37 | Q4: 13 | R4: 3 | S4: 5 | T4: 13 | U4: 3 | V4: 5 | W4: 13 | X4: 3 | Y4: 5 | Z4: =SUM(W4,X4,Y4) -> 21 | AC4: 0 | AD4: 0 | AE4: 0 | AF4: 2 | AG4: 26 | AH4: 2 | AI4: 1
A5: A = number of target thought mentions only, B = number of bell rings only, C = number of thought mentions and bell rings at the same time | D5: 1004 | E5: 2 | F5: 4 | G5: 20 | H5: 13 | I5: 2 | J5: 20 | K5: 13 | L5: 2 | M5: 20 | N5: 13 | O5: 2 | P5: =SUM(M5,Q5,N5,O5) -> 43 | Q5: 8 | R5: 14 | S5: 12 | T5: 8 | U5: 14 | V5: 12 | W5: 8 | X5: 14 | Y5: 12 | Z5: =SUM(W5,X5,Y5) -> 34 | AC5: 1 | AD5: 1 | AE5: 1 | AF5: 2 | AG5: 18 | AH5: 2 | AI5: 1
A6: Period 1 only needs to be completed for initial concentration group | C6: Start data entry here from 1 onwards | D6: 1 | E6: 2 | F6: 1 | G6: 1 | H6: 0 | I6: 8 | J6: 0 | K6: 1 | L6: 9 | M6: 1 | N6: 1 | O6: 8 | P6: =SUM(M6,Q6,N6,O6) -> 11 | Q6: 1 | R6: 2 | S6: 3 | T6: 0 | U6: 2 | V6: 4 | W6: 1 | X6: 2 | Y6: 3 | Z6: =SUM(W6,X6,Y6) -> 6 | AA6: 40 | AB6: 20 | AC6: 0 | AD6: 0 | AE6: 0 | AF6: 1 | AG6: 19 | AH6: 1 | AI6: 1
A7: Final = results after resolving any inter-coder discrepancies | D7: 2 | E7: 2 | F7: 2 | G7: 3 | H7: 3 | I7: 1 | J7: 4 | K7: 3 | L7: 1 | M7: 4 | N7: 3 | O7: 1 | P7: =SUM(M7,Q7,N7,O7) -> 9 | Q7: 1 | R7: 2 | S7: 0 | T7: 1 | U7: 2 | V7: 0 | W7: 1 | X7: 2 | Y7: 0 | Z7: =SUM(W7,X7,Y7) -> 3 | AA7: 70 | AB7: 40 | AC7: 0 | AD7: 0 | AE7: 0 | AI7: 1
A8: Percentage = % time participant indicate to be thinking about target thought | D8: 3 | E8: 2 | F8: 3 | G8: 31 | H8: 3 | I8: 5 | J8: 19 | K8: 3 | L8: 5 | M8: 25 | N8: 3 | O8: 5 | P8: =SUM(M8,Q8,N8,O8) -> 56 | Q8: 23 | R8: 1 | S8: 2 | T8: 14 | U8: 1 | V8: 2 | W8: 19 | X8: 1 | Y8: 2 | Z8: =SUM(W8,X8,Y8) -> 22 | AA8: 60 | AB8: 40 | AC8: 0 | AD8: 0 | AE8: 0 | AF8: 1 | AG8: 19 | AH8: 1 | AI8: 1
A9: Probe: did participant fail probe - 1 = yes, 0 = no (to be completed | D9: 4 | E9: 2 | F9: 4 | G9: 27 | H9: 1 | I9: 1 | J9: 16 | K9: 1 | L9: 1 | M9: 22 | N9: 1 | O9: 1 | P9: =SUM(M9,Q9,N9,O9) -> 48 | Q9: 24 | R9: 0 | S9: 0 | T9: 13 | U9: 0 | V9: 0 | W9: 19 | X9: 0 | Y9: 0 | Z9: =SUM(W9,X9,Y9) -> 19 | AA9: 30 | AB9: 70 | AC9: 0 | AD9: 0 | AE9: 0 | AF9: 1 | AG9: 18 | AH9: 2 | AI9: 1
A10: by two independent coders AFTER termination of data collection) | D10: 5 | E10: 1 | F10: 1 | Q10: 1 | R10: 2 | S10: 16 | T10: 1 | U10: 2 | V10: 16 | W10: 1 | X10: 2 | Y10: 16 | Z10: =SUM(W10,X10,Y10) -> 19 | AA10: 50 | AB10: 30 | AC10: 0 | AD10: 0 | AE10: 0 | AF10: 1 | AG10: 20 | AH10: 1 | AI10: 1
A11: MC = manipulation check (think = 1, not think = 2) | D11: 6 | E11: 1 | F11: 2 | Q11: 0 | R11: 1 | S11: 1 | T11: 0 | U11: 2 | V11: 1 | W11: 0 | X11: 2 | Y11: 1 | Z11: =SUM(W11,X11,Y11) -> 3 | AA11: 50 | AB11: 50 | AC11: 0 | AD11: 0 | AE11: 0 | AF11: 1 | AG11: 20 | AH11: 2 | AI11: 1
A12: Gender: female = 1, male = 2, other = 3, prefer not to say = 4 | D12: 7 | E12: 1 | F12: 3 | Q12: 40 | R12: 1 | S12: 4 | T12: 15 | U12: 2 | V12: 3 | W12: 28 | X12: 1 | Y12: 4 | Z12: =SUM(W12,X12,Y12) -> 33 | AA12: 30 | AB12: 70 | AC12: 0 | AD12: 0 | AE12: 0 | AF12: 1 | AG12: 19 | AH12: 2 | AI12: 1
A13: Compliance: complied with experimental instructions? Yes = 1, No = 2 | D13: 8 | E13: 1 | F13: 4 | Q13: 2 | R13: 1 | S13: 10 | T13: 3 | U13: 1 | V13: 11 | W13: 2 | X13: 1 | Y13: 11 | Z13: =SUM(W13,X13,Y13) -> 14 | AA13: 70 | AB13: 90 | AC13: 0 | AD13: 0 | AE13: 0 | AF13: 2 | AG13: 18 | AH13: 1 | AI13: 1
D14: 9 | E14: 2 | F14: 1 | G14: 0 | H14: 1 | I14: 14 | J14: 0 | K14: 2 | L14: 13 | M14: 0 | N14: 1 | O14: 14 | P14: =SUM(M14,Q14,N14,O14) -> 15 | Q14: 0 | R14: 2 | S14: 9 | T14: 0 | U14: 3 | V14: 8 | W14: 0 | X14: 2 | Y14: 9 | Z14: =SUM(W14,X14,Y14) -> 11 | AA14: 40 | AB14: 25 | AC14: 0 | AD14: 0 | AE14: 0 | AF14: 1 | AG14: 25 | AH14: 2 | AI14: 1
D15: 10 | E15: 2 | F15: 2 | G15: 10 | H15: 7 | I15: 28 | J15: 5 | K15: 4 | L15: 31 | M15: 6 | N15: 5 | O15: 31 | P15: =SUM(M15,Q15,N15,O15) -> 48 | Q15: 6 | R15: 10 | S15: 21 | T15: 0 | U15: 7 | V15: 24 | W15: 3 | X15: 8 | Y15: 23 | Z15: =SUM(W15,X15,Y15) -> 34 | AA15: 85 | AB15: 70 | AC15: 0 | AD15: 0 | AE15: 0 | AF15: 1 | AG15: 18 | AH15: 2 | AI15: 1
D16: 11 | E16: 2 | F16: 3 | G16: 4 | H16: 0 | I16: 2 | J16: 5 | K16: 0 | L16: 3 | M16: 4 | N16: 0 | O16: 3 | P16: =SUM(M16,Q16,N16,O16) -> 7 | Q16: 0 | R16: 0 | S16: 0 | T16: 0 | U16: 0 | V16: 0 | W16: 0 | X16: 0 | Y16: 0 | Z16: =SUM(W16,X16,Y16) -> 0 | AA16: 10 | AB16: 0 | AC16: 0 | AD16: 0 | AE16: 0 | AG16: 30 | AH16: 2 | AI16: 1
D17: 12 | E17: 2 | F17: 4 | G17: 18 | H17: 0 | I17: 7 | J17: 11 | K17: 0 | L17: 7 | M17: 15 | N17: 0 | O17: 7 | P17: =SUM(M17,Q17,N17,O17) -> 37 | Q17: 15 | R17: 0 | S17: 4 | T17: 10 | U17: 0 | V17: 4 | W17: 13 | X17: 0 | Y17: 4 | Z17: =SUM(W17,X17,Y17) -> 17 | AA17: 90 | AB17: 97 | AC17: 0 | AD17: 0 | AE17: 0 | AF17: 1 | AG17: 19 | AH17: 1 | AI17: 1
D18: 13 | E18: 1 | F18: 1 | Q18: 6 | R18: 1 | S18: 9 | T18: 4 | U18: 1 | V18: 9 | W18: 5 | X18: 1 | Y18: 9 | Z18: =SUM(W18,X18,Y18) -> 15 | AA18: 15 | AB18: 40 | AC18: 0 | AD18: 0 | AE18: 0 | AF18: 2 | AG18: 18 | AH18: 2 | AI18: 1
D19: 14 | E19: 1 | F19: 2 | Q19: 6 | R19: 4 | S19: 9 | T19: 6 | U19: 4 | V19: 10 | W19: 6 | X19: 4 | Y19: 10 | Z19: =SUM(W19,X19,Y19) -> 20 | AA19: 45 | AB19: 100 | AC19: 0 | AD19: 0 | AE19: 0 | AF19: 2 | AG19: 22 | AH19: 1 | AI19: 1
D20: 15 | E20: 1 | F20: 3 | Q20: 6 | R20: 6 | S20: 7 | T20: 3 | U20: 6 | V20: 8 | W20: 2 | X20: 6 | Y20: 1 | Z20: =SUM(W20,X20,Y20) -> 9 | AA20: 60 | AB20: 75 | AC20: 0 | AD20: 0 | AE20: 0 | AF20: 2 | AG20: 20 | AH20: 1 | AI20: 1
D21: 16 | E21: 1 | F21: 4 | Q21: 5 | R21: 0 | S21: 14 | T21: 5 | U21: 1 | V21: 13 | W21: 5 | X21: 0 | Y21: 14 | Z21: =SUM(W21,X21,Y21) -> 19 | AA21: 10 | AB21: 90 | AC21: 0 | AD21: 0 | AE21: 0 | AF21: 1 | AG21: 18 | AH21: 1 | AI21: 1
D22: 17 | E22: 2 | F22: 1 | G22: 0 | H22: 18 | I22: 3 | J22: 0 | K22: 15 | L22: 3 | M22: 0 | N22: 18 | O22: 3 | P22: =SUM(M22,Q22,N22,O22) -> 21 | Q22: 0 | R22: 15 | S22: 1 | T22: 0 | U22: 15 | V22: 1 | W22: 0 | X22: 15 | Y22: 1 | Z22: =SUM(W22,X22,Y22) -> 16 | AA22: 20 | AB22: 10 | AC22: 0 | AD22: 0 | AE22: 0 | AF22: 1 | AG22: 22 | AH22: 1 | AI22: 1
D23: 18 | E23: 2 | F23: 2 | G23: 4 | H23: 9 | I23: 3 | J23: 2 | K23: 7 | L23: 4 | M23: 3 | N23: 7 | O23: 4 | P23: =SUM(M23,Q23,N23,O23) -> 14 | Q23: 0 | R23: 4 | S23: 4 | T23: 0 | U23: 4 | V23: 4 | W23: 0 | X23: 4 | Y23: 4 | Z23: =SUM(W23,X23,Y23) -> 8 | AA23: 40 | AB23: 10 | AC23: 0 | AD23: 0 | AE23: 0 | AF23: 1 | AG23: 18 | AH23: 1 | AI23: 1
D24: 19 | E24: 2 | F24: 3 | G24: 2 | H24: 0 | I24: 3 | J24: 2 | K24: 0 | L24: 3 | M24: 2 | N24: 0 | O24: 0 | P24: =SUM(M24,Q24,N24,O24) -> 4 | Q24: 2 | R24: 0 | S24: 6 | T24: 0 | U24: 0 | V24: 6 | W24: 2 | X24: 0 | Y24: 6 | Z24: =SUM(W24,X24,Y24) -> 8 | AA24: 50 | AB24: 70 | AC24: 0 | AD24: 0 | AE24: 0 | AF24: 1 | AG24: 19 | AH24: 2 | AI24: 1
D25: 20 | E25: 2 | F25: 4 | G25: 6 | H25: 12 | I25: 5 | J25: 3 | K25: 9 | L25: 8 | M25: 4 | N25: 10 | O25: 7 | P25: =SUM(M25,Q25,N25,O25) -> 29 | Q25: 8 | R25: 3 | S25: 7 | T25: 4 | U25: 3 | V25: 8 | W25: 6 | X25: 3 | Y25: 8 | Z25: =SUM(W25,X25,Y25) -> 17 | AA25: 90 | AB25: 85 | AC25: 0 | AD25: 0 | AE25: 0 | AF25: 2 | AG25: 18 | AH25: 1 | AI25: 1
D26: 21 | E26: 1 | F26: 1 | Q26: 4 | R26: 8 | S26: 3 | T26: 3 | U26: 8 | V26: 3 | W26: 4 | X26: 8 | Y26: 3 | Z26: =SUM(W26,X26,Y26) -> 15 | AA26: 13 | AB26: 85 | AC26: 0 | AD26: 0 | AE26: 0 | AF26: 1 | AG26: 20 | AH26: 1 | AI26: 1
D27: 22 | E27: 1 | F27: 2 | Q27: 37 | R27: 1 | S27: 8 | T27: 29 | U27: 1 | V27: 8 | W27: 33 | X27: 1 | Y27: 8 | Z27: =SUM(W27,X27,Y27) -> 42 | AA27: 1 | AB27: 100 | AC27: 0 | AD27: 0 | AE27: 0 | AF27: 2 | AG27: 20 | AH27: 1 | AI27: 1
D28: 23 | E28: 1 | F28: 3 | Q28: 9 | R28: 0 | S28: 8 | T28: 6 | U28: 1 | V28: 7 | W28: 7 | X28: 0 | Y28: 8 | Z28: =SUM(W28,X28,Y28) -> 15 | AA28: 30 | AB28: 70 | AC28: 0 | AD28: 0 | AE28: 0 | AF28: 2 | AG28: 19 | AH28: 1 | AI28: 1
D29: 24 | E29: 1 | F29: 4 | Q29: 34 | R29: 0 | S29: 4 | T29: 23 | U29: 0 | V29: 4 | W29: 29 | X29: 0 | Y29: 4 | Z29: =SUM(W29,X29,Y29) -> 33 | AA29: 5 | AB29: 90 | AC29: 0 | AD29: 0 | AE29: 0 | AF29: 1 | AG29: 19 | AH29: 1 | AI29: 1
D30: 25 | E30: 2 | F30: 1 | G30: 6 | H30: 3 | I30: 19 | J30: 4 | K30: 3 | L30: 17 | M30: 5 | N30: 3 | O30: 18 | P30: =SUM(M30,Q30,N30,O30) -> 32 | Q30: 6 | R30: 3 | S30: 9 | T30: 4 | U30: 3 | V30: 9 | W30: 5 | X30: 3 | Y30: 9 | Z30: =SUM(W30,X30,Y30) -> 17 | AA30: 90 | AB30: 70 | AC30: 0 | AD30: 0 | AE30: 0 | AF30: 1 | AG30: 19 | AH30: 1 | AI30: 1
D31: 26 | E31: 2 | F31: 2 | G31: 2 | H31: 0 | I31: 13 | J31: 1 | K31: 0 | L31: 13 | M31: 2 | N31: 0 | O31: 13 | P31: =SUM(M31,Q31,N31,O31) -> 16 | Q31: 1 | R31: 8 | S31: 17 | T31: 1 | U31: 8 | V31: 16 | W31: 1 | X31: 8 | Y31: 17 | Z31: =SUM(W31,X31,Y31) -> 26 | AA31: 70 | AB31: 65 | AC31: 0 | AD31: 0 | AE31: 0 | AF31: 1 | AG31: 18 | AH31: 1 | AI31: 1
D32: 27 | E32: 2 | F32: 3 | G32: 22 | H32: 0 | I32: 24 | J32: 8 | K32: 2 | L32: 23 | M32: 15 | N32: 1 | O32: 24 | P32: =SUM(M32,Q32,N32,O32) -> 50 | Q32: 10 | R32: 1 | S32: 43 | T32: 2 | U32: 4 | V32: 39 | W32: 6 | X32: 2 | Y32: 41 | Z32: =SUM(W32,X32,Y32) -> 49 | AA32: 98 | AB32: 95 | AC32: 0 | AD32: 0 | AE32: 0 | AF32: 1 | AG32: 20 | AH32: 1 | AI32: 1
D33: 28 | E33: 2 | F33: 4 | G33: 22 | H33: 0 | I33: 17 | J33: 11 | K33: 2 | L33: 14 | M33: 16 | N33: 1 | O33: 16 | P33: =SUM(M33,Q33,N33,O33) -> 45 | Q33: 12 | R33: 0 | S33: 18 | T33: 10 | U33: 7 | V33: 11 | W33: 11 | X33: 3 | Y33: 14 | Z33: =SUM(W33,X33,Y33) -> 28 | AA33: 85 | AB33: 90 | AC33: 0 | AD33: 0 | AE33: 0 | AF33: 1 | AG33: 20 | AH33: 1 | AI33: 1
D34: 29 | E34: 1 | F34: 1 | Q34: 6 | R34: 8 | S34: 17 | T34: 9 | U34: 6 | V34: 13 | W34: 7 | X34: 7 | Y34: 15 | Z34: =SUM(W34,X34,Y34) -> 29 | AA34: 25 | AB34: 75 | AC34: 0 | AD34: 0 | AE34: 0 | AF34: 1 | AG34: 22 | AH34: 1 | AI34: 1
D35: 30 | E35: 1 | F35: 2 | Q35: 0 | R35: 0 | S35: 2 | T35: 0 | U35: 0 | V35: 2 | W35: 0 | X35: 0 | Y35: 2 | Z35: =SUM(W35,X35,Y35) -> 2 | AA35: 10 | AB35: 5 | AC35: 0 | AD35: 0 | AE35: 0 | AF35: 1 | AG35: 19 | AH35: 1 | AI35: 1
D36: 31 | E36: 1 | F36: 3 | Q36: 2 | R36: 0 | S36: 2 | T36: 1 | U36: 0 | V36: 2 | W36: 2 | X36: 0 | Y36: 2 | Z36: =SUM(W36,X36,Y36) -> 4 | AA36: 0 | AB36: 10 | AC36: 0 | AD36: 0 | AE36: 0 | AF36: 2 | AG36: 18 | AH36: 2 | AI36: 1
D37: 32 | E37: 1 | F37: 4 | Q37: 6 | R37: 3 | S37: 5 | T37: 4 | U37: 4 | V37: 4 | W37: 5 | X37: 4 | Y37: 4 | Z37: =SUM(W37,X37,Y37) -> 13 | AA37: 5 | AB37: 90 | AC37: 0 | AD37: 0 | AE37: 0 | AF37: 2 | AG37: 20 | AH37: 1 | AI37: 1
D38: 33 | E38: 2 | F38: 1 | G38: 0 | H38: 0 | I38: 1 | J38: 0 | K38: 0 | L38: 1 | M38: 0 | N38: 0 | O38: 1 | P38: =SUM(M38,Q38,N38,O38) -> 1 | Q38: 0 | R38: 2 | S38: 0 | T38: 0 | U38: 2 | V38: 0 | W38: 0 | X38: 2 | Y38: 0 | Z38: =SUM(W38,X38,Y38) -> 2 | AA38: 10 | AB38: 30 | AC38: 0 | AD38: 0 | AE38: 0 | AF38: 1 | AG38: 20 | AH38: 1 | AI38: 1
D39: 34 | E39: 2 | F39: 2 | G39: 0 | H39: 0 | I39: 11 | J39: 0 | K39: 0 | L39: 11 | M39: 0 | N39: 0 | O39: 11 | P39: =SUM(M39,Q39,N39,O39) -> 18 | Q39: 7 | R39: 0 | S39: 9 | T39: 2 | U39: 0 | V39: 10 | W39: 4 | X39: 0 | Y39: 10 | Z39: =SUM(W39,X39,Y39) -> 14 | AA39: 97 | AB39: 91 | AC39: 0 | AD39: 0 | AE39: 0 | AF39: 1 | AG39: 22 | AH39: 1 | AI39: 1
D40: 35 | E40: 2 | F40: 3 | G40: 9 | H40: 3 | I40: 3 | J40: 3 | K40: 3 | L40: 3 | M40: 6 | N40: 3 | O40: 3 | P40: =SUM(M40,Q40,N40,O40) -> 15 | Q40: 3 | R40: 0 | S40: 1 | T40: 0 | U40: 0 | V40: 1 | W40: 3 | X40: 0 | Y40: 1 | Z40: =SUM(W40,X40,Y40) -> 4 | AA40: 75 | AB40: 20 | AC40: 0 | AD40: 0 | AE40: 0 | AF40: 2 | AG40: 19 | AH40: 2 | AI40: 1
...

Sheet summarystats
A1: Correct responses
B2: Concentration | C2: Suppression
A3: High time pressure | B3: =AVERAGEIF(testdata!$E$2:$E$11, "Concentration", testdata!#REF!) -> #REF! | C3: =AVERAGEIF(testdata!$E$2:$E$11, "Suppression", testdata!#REF!) -> #REF!
A4: Low time pressure | B4: =AVERAGEIF(testdata!$E$2:$E$11, "Concentration", testdata!#REF!) -> #REF! | C4: =AVERAGEIF(testdata!$E$2:$E$11, "Suppression", testdata!#REF!) -> #REF!
A6: RT responses
B7: Concentration | C7: Suppression
A8: High time pressure | B8: =AVERAGEIF(testdata!$E$2:$E$11, "Concentration", testdata!#REF!) -> #REF! | C8: =AVERAGEIF(testdata!$E$2:$E$11, "Suppression", testdata!#REF!) -> #REF!
A9: Low time pressure | B9: =AVERAGEIF(testdata!$E$2:$E$11, "Concentration", testdata!#REF!) -> #REF! | C9: =AVERAGEIF(testdata!$E$2:$E$11, "Suppression", testdata!#REF!) -> #REF!
