Workbook

Sheet Meilan (before resolving)
A1: Notes: | D1: ParticipantID | E1: Condition | F1: Targetword | G1: A_period.1.coder1 | H1: B_period.1.coder1 | I1: C_period.1.coder1 | J1: A_period.1.coder2 | K1: B_period.1.coder2 | L1: C_period.1.coder2 | M1: A_period.1.final | N1: B_period.1.final | O1: C_period.1.final | P1: sum.of.ABC_period.1.final | Q1: A_period.2.coder1 | R1: B_period.2.coder1 | S1: C_period.2.coder1 | T1: A_period.2.coder2 | U1: B_period.2.coder2 | V1: C_period.2.coder2 | W1: A_period.2.final | X1: B_period.2.final | Y1: C_period.2.final | Z1: sum.ABC_period2.final | AA1: Percentage.round.1 | AB1: Percentage.round.2 | AC1: probe.coder1 | AD1: probe.coder2 | AE1: probe.final | AF1: MC | AG1: age | AH1: gender | AI1: Compliance
A2: Condition (initial suppression = 1, initial concentration = 2) | C2: Example | D2: 1001 | E2: 1 | F2: 1 | G2: 18 | H2: 4 | I2: 8 | J2: 18 | K2: 4 | L2: 8 | M2: 18 | N2: 4 | O2: 8 | P2: =SUM(M2,Q2,N2,O2) -> 44 | Q2: 14 | R2: 15 | S2: 20 | T2: 14 | U2: 15 | V2: 20 | W2: 14 | X2: 15 | Y2: 20 | Z2: =SUM(W2,X2,Y2) -> 49 | AC2: 0 | AD2: 0 | AE2: 0 | AF2: 1 (think) | AG2: 30 | AH2: 1 | AI2: 1 (yes)
A3: Target word (gorilla = 1, tiger = 2, food = 3, diseases = 4) | D3: 1002 | E3: 1 | F3: 2 | G3: 18 | H3: 16 | I3: 16 | J3: 18 | K3: 16 | L3: 16 | M3: 18 | N3: 16 | O3: 16 | P3: =SUM(M3,Q3,N3,O3) -> 63 | Q3: 13 | R3: 16 | S3: 15 | T3: 13 | U3: 16 | V3: 15 | W3: 13 | X3: 16 | Y3: 15 | Z3: =SUM(W3,X3,Y3) -> 44 | AC3: 0 | AD3: 1 | AE3: 0 | AF3: 1 | AG3: 25 | AH3: 1 | AI3: 1
A4: Participant ID should start from 121 rather than 001 | D4: 1003 | E4: 2 | F4: 3 | G4: 2 | H4: 3 | I4: 19 | J4: 2 | K4: 3 | L4: 19 | M4: 2 | N4: 3 | O4: 19 | P4: =SUM(M4,Q4,N4,O4) -> 37 | Q4: 13 | R4: 3 | S4: 5 | T4: 13 | U4: 3 | V4: 5 | W4: 13 | X4: 3 | Y4: 5 | Z4: =SUM(W4,X4,Y4) -> 21 | AC4: 0 | AD4: 0 | AE4: 0 | AF4: 2 (not think) | AG4: 26 | AH4: 2 | AI4: 1
A5: A = number of target thought mentions only, B = number of bell rings only, C = number of thought mentions and bell rings at the same time | D5: 1004 | E5: 2 | F5: 4 | G5: 20 | H5: 13 | I5: 2 | J5: 20 | K5: 13 | L5: 2 | M5: 20 | N5: 13 | O5: 2 | P5: =SUM(M5,Q5,N5,O5) -> 43 | Q5: 8 | R5: 14 | S5: 12 | T5: 8 | U5: 14 | V5: 12 | W5: 8 | X5: 14 | Y5: 12 | Z5: =SUM(W5,X5,Y5) -> 34 | AC5: 1 | AD5: 1 | AE5: 1 | AF5: 2 | AG5: 18 | AH5: 2 | AI5: 1
A6: Period 1 only needs to be completed for initial concentration group | C6: Start data entry here from 1 onwards | D6: 100161 | E6: 1 | F6: 1 | T6: 0 | U6: 0 | V6: 0 | AA6: 0 | AB6: 1 | AD6: 0 | AF6: 2 | AG6: 20 | AH6: 1 | AI6: 1
A7: Final = results after resolving any inter-coder discrepancies | D7: 104496 | E7: 1 | F7: 2 | T7: 0 | U7: 0 | V7: 0 | AA7: 0 | AB7: 10 | AD7: 0 | AF7: 2 | AG7: 19 | AH7: 1 | AI7: 1
A8: Percentage = % time participant indicate to be thinking about target thought | D8: 117872 | E8: 2 | F8: 2 | J8: 24 | K8: 5 | L8: 12 | AA8: 0 | AB8: 60 | AD8: 0 | AF8: 1 | AG8: 23 | AH8: 2 | AI8: 1
A9: Probe: did participant fail probe - 1 = yes, 0 = no (to be completed | D9: 120073 | E9: 2 | F9: 2 | J9: 16 | K9: 0 | L9: 3 | AA9: 0 | AB9: 60 | AD9: 0 | AF9: 1 | AG9: 20 | AH9: 1 | AI9: 1
A10: by two independent coders AFTER termination of data collection) | D10: 122535 | E10: 1 | F10: 1 | T10: 0 | U10: 3 | V10: 0 | AA10: 0 | AB10: 40 | AD10: 1 | AF10: 2 | AG10: 22 | AH10: 1 | AI10: 1
A11: MC = manipulation check (think = 1, not think = 2) | D11: 128377 | E11: 2 | F11: 1 | J11: 21 | K11: 4 | L11: 6 | AA11: 0 | AB11: 60 | AD11: 0 | AF11: 1 | AG11: 23 | AH11: 2 | AI11: 1
A12: Gender: female = 1, male = 2, other = 3, prefer not to say = 4 | D12: 143217 | E12: 2 | F12: 4 | J12: 33 | K12: 1 | L12: 5 | AA12: 85 | AB12: 87 | AD12: 0 | AF12: 1 | AG12: 22 | AH12: 1 | AI12: 1
A13: Compliance: complied with experimental instructions? Yes = 1, No = 2 | D13: 155583 | E13: 2 | F13: 1 | J13: 28 | K13: 4 | L13: 5 | AA13: 0 | AB13: 70 | AD13: 0 | AF13: 1 | AG13: 19 | AH13: 1 | AI13: 1
D14: 160903 | E14: 2 | F14: 4 | J14: 26 | K14: 0 | L14: 7 | AA14: 0 | AB14: 90 | AD14: 0 | AF14: 1 | AG14: 20 | AH14: 1 | AI14: 1
D15: 170171 | E15: 1 | F15: 4 | T15: 0 | U15: 4 | V15: 0 | AA15: 0 | AB15: 40 | AD15: 1 | AF15: 2 | AG15: 19 | AH15: 1 | AI15: 1
D16: 194097 | E16: 2 | F16: 1 | J16: 9 | K16: 9 | L16: 8 | AA16: 0 | AB16: 80 | AD16: 0 | AF16: 1 | AG16: 20 | AH16: 1 | AI16: 1
D17: 197532 | E17: 2 | F17: 4 | J17: 12 | K17: 0 | L17: 9 | AA17: 0 | AB17: 90 | AD17: 0 | AF17: 1 | AG17: 21 | AH17: 1 | AI17: 1
D18: 197689 | E18: 1 | F18: 3 | T18: 1 | U18: 7 | V18: 0 | AA18: 2 | AB18: 65 | AD18: 1 | AF18: 2 | AG18: 23 | AH18: 1 | AI18: 2
D19: 199134 | E19: 1 | F19: 3 | T19: 0 | U19: 3 | V19: 1 | AA19: 50 | AB19: 20 | AD19: 1 | AF19: 2 | AG19: 20 | AH19: 1 | AI19: 1
D20: 203165 | E20: 1 | F20: 2 | T20: 3 | U20: 4 | V20: 7 | AA20: 0 | AB20: 20 | AD20: 1 | AF20: 2 | AG20: 18 | AH20: 1 | AI20: 1
D21: 205813 | E21: 1 | F21: 1 | T21: 2 | U21: 3 | V21: 0 | AA21: 0 | AB21: 2 | AD21: 1 | AF21: 2 | AG21: 19 | AH21: 1 | AI21: 1
D22: 215393 | E22: 1 | F22: 3 | T22: 0 | U22: 8 | V22: 2 | AA22: 0 | AB22: 40 | AD22: 1 | AF22: 2 | AG22: 19 | AH22: 1 | AI22: 1
D23: 222449 | E23: 1 | F23: 1 | T23: 0 | U23: 0 | V23: 0 | AA23: 0 | AB23: 20 | AD23: 0 | AF23: 2 | AG23: 19 | AH23: 1 | AI23: 1
D24: 224807 | E24: 1 | F24: 2 | T24: 0 | U24: 0 | V24: 0 | AA24: 0 | AB24: 20 | AD24: 0 | AF24: 2 | AG24: 23 | AH24: 2 | AI24: 1
D25: 243885 | E25: 1 | F25: 3 | T25: 0 | U25: 0 | V25: 0 | AA25: 90 | AB25: 100 | AD25: 0 | AF25: 2 | AG25: 19 | AH25: 1 | AI25: 1
D26: 250971 | E26: 1 | F26: 2 | T26: 0 | U26: 2 | V26: 3 | AA26: 0 | AB26: 10 | AD26: 1 | AF26: 2 | AG26: 18 | AH26: 1 | AI26: 1
D27: 256240 | E27: 2 | F27: 3 | J27: 7 | K27: 19 | L27: 23 | AA27: 5 | AB27: 90 | AD27: 0 | AF27: 1 | AG27: 25 | AH27: 2 | AI27: 1
D28: 262983 | E28: 2 | F28: 2 | J28: 3 | K28: 2 | L28: 3 | AA28: 0 | AB28: 40 | AD28: 0 | AF28: 1 | AG28: 19 | AH28: 1 | AI28: 1
D29: 264413 | E29: 2 | F29: 3 | J29: 11 | K29: 5 | L29: 10 | AA29: 10 | AB29: 90 | AD29: 0 | AF29: 1 | AG29: 19 | AH29: 1 | AI29: 1
D30: 265399 | E30: 2 | F30: 3 | J30: 28 | K30: 1 | L30: 8 | AA30: 0 | AB30: 100 | AD30: 0 | AF30: 1 | AG30: 21 | AH30: 1 | AI30: 1
D31: 277194 | E31: 1 | F31: 1 | T31: 0 | U31: 2 | V31: 0 | AA31: 0 | AB31: 20 | AD31: 1 | AF31: 2 | AG31: 21 | AH31: 1 | AI31: 1
D32: 310918 | E32: 2 | F32: 4 | J32: 21 | K32: 6 | L32: 0 | AA32: 0 | AB32: 70 | AD32: 0 | AF32: 1 | AG32: 22 | AH32: 2 | AI32: 1
D33: 315045 | E33: 1 | F33: 3 | T33: 1 | U33: 3 | V33: 1 | AA33: 10 | AB33: 20 | AD33: 0 | AF33: 2 | AG33: 21 | AH33: 1 | AI33: 1
D34: 326586 | E34: 1 | F34: 2 | T34: 0 | U34: 2 | V34: 1 | AA34: 0 | AB34: 20 | AD34: 1 | AF34: 2 | AG34: 21 | AH34: 1 | AI34: 1
D35: 330133 | E35: 2 | F35: 3 | J35: 18 | K35: 0 | L35: 4 | AA35: 15 | AB35: 90 | AD35: 0 | AF35: 1 | AG35: 29 | AH35: 2 | AI35: 1
D36: 341963 | E36: 2 | F36: 4 | J36: 5 | K36: 0 | L36: 12 | AA36: 0 | AB36: 80 | AD36: 0 | AF36: 1 | AG36: 21 | AH36: 1 | AI36: 1
D37: 352082 | E37: 1 | F37: 1 | T37: 4 | U37: 1 | V37: 4 | AA37: 0 | AB37: 20 | AD37: 1 | AF37: 2 | AG37: 20 | AH37: 1 | AI37: 1
D38: 354902 | E38: 2 | F38: 2 | J38: 0 | K38: 3 | L38: 1 | AA38: 0 | AB38: 10 | AD38: 0 | AF38: 1 | AG38: 20 | AH38: 1 | AI38: 1
D39: 367470 | E39: 1 | F39: 1 | T39: 0 | U39: 0 | V39: 2 | AA39: 0 | AB39: 2 | AD39: 1 | AF39: 2 | AG39: 22 | AH39: 1 | AI39: 1
D40: 377404 | E40: 1 | F40: 2 | T40: 2 | U40: 5 | V40: 0 | AA40: 0 | AB40: 60 | AD40: 1 | AF40: 2 | AG40: 23 | AH40: 1 | AI40: 1
...

Sheet Noelle (resolving)
A1: Notes: | D1: ParticipantID | E1: Condition | F1: Targetword | G1: A_period.1.coder1 | H1: B_period.1.coder1 | I1: C_period.1.coder1 | J1: A_period.1.coder2 | K1: B_period.1.coder2 | L1: C_period.1.coder2 | M1: A_period.1.final | N1: B_period.1.final | O1: C_period.1.final | P1: sum.of.ABC_period.1.final | Q1: A_period.2.coder1 | R1: B_period.2.coder1 | S1: C_period.2.coder1 | T1: A_period.2.coder2 | U1: B_period.2.coder2 | V1: C_period.2.coder2 | W1: A_period.2.final | X1: B_period.2.final | Y1: C_period.2.final | Z1: sum.ABC_period2.final | AA1: Percentage.round.1 | AB1: Percentage.round.2 | AC1: probe.coder1 | AD1: probe.coder2 | AE1: probe.final | AF1: MC | AG1: age | AH1: gender | AI1: Compliance
A2: Condition (initial suppression = 1, initial concentration = 2) | C2: Example | D2: 1001 | E2: 1 | F2: 1 | G2: 18 | H2: 4 | I2: 8 | J2: 18 | K2: 4 | L2: 8 | M2: 18 | N2: 4 | O2: 8 | P2: =SUM(M2,Q2,N2,O2) -> 44 | Q2: 14 | R2: 15 | S2: 20 | T2: 14 | U2: 15 | V2: 20 | W2: 14 | X2: 15 | Y2: 20 | Z2: =SUM(W2,X2,Y2) -> 49 | AC2: 0 | AD2: 0 | AE2: 0 | AF2: 1 | AG2: 30 | AH2: 1 | AI2: 1
A3: Target word (gorilla = 1, tiger = 2, food = 3, diseases = 4) | D3: 1002 | E3: 1 | F3: 2 | G3: 18 | H3: 16 | I3: 16 | J3: 18 | K3: 16 | L3: 16 | M3: 18 | N3: 16 | O3: 16 | P3: =SUM(M3,Q3,N3,O3) -> 63 | Q3: 13 | R3: 16 | S3: 15 | T3: 13 | U3: 16 | V3: 15 | W3: 13 | X3: 16 | Y3: 15 | Z3: =SUM(W3,X3,Y3) -> 44 | AC3: 0 | AD3: 1 | AE3: 0 | AF3: 1 | AG3: 25 | AH3: 1 | AI3: 1
A4: Participant ID should start from 121 rather than 001 | D4: 1003 | E4: 2 | F4: 3 | G4: 2 | H4: 3 | I4: 19 | J4: 2 | K4: 3 | L4: 19 | M4: 2 | N4: 3 | O4: 19 | P4: =SUM(M4,Q4,N4,O4) -> 37 | Q4: 13 | R4: 3 | S4: 5 | T4: 13 | U4: 3 | V4: 5 | W4: 13 | X4: 3 | Y4: 5 | Z4: =SUM(W4,X4,Y4) -> 21 | AC4: 0 | AD4: 0 | AE4: 0 | AF4: 2 | AG4: 26 | AH4: 2 | AI4: 1
A5: A = number of target thought mentions only, B = number of bell rings only, C = number of thought mentions and bell rings at the same time | D5: 1004 | E5: 2 | F5: 4 | G5: 20 | H5: 13 | I5: 2 | J5: 20 | K5: 13 | L5: 2 | M5: 20 | N5: 13 | O5: 2 | P5: =SUM(M5,Q5,N5,O5) -> 43 | Q5: 8 | R5: 14 | S5: 12 | T5: 8 | U5: 14 | V5: 12 | W5: 8 | X5: 14 | Y5: 12 | Z5: =SUM(W5,X5,Y5) -> 34 | AC5: 1 | AD5: 1 | AE5: 1 | AF5: 2 | AG5: 18 | AH5: 2 | AI5: 1
A6: Period 1 only needs to be completed for initial concentration group | C6: Start data entry here from 1 onwards | D6: 100161 | E6: 1 | F6: 1 | Q6: 0 | R6: 0 | S6: 0 | AA6: 0 | AB6: 1 | AC6: 0 | AF6: 2 | AG6: 20 | AH6: 1 | AI6: 1
A7: Final = results after resolving any inter-coder discrepancies | D7: 104496 | E7: 1 | F7: 2 | Q7: 0 | R7: 0 | S7: 0 | AA7: 0 | AB7: 10 | AC7: 0 | AF7: 1 | AG7: 19 | AH7: 1 | AI7: 1
A8: Percentage = % time participant indicate to be thinking about target thought | D8: 117872 | E8: 2 | F8: 2 | G8: 20 | H8: 7 | I8: 14 | AA8: 0 | AB8: 60 | AC8: 0 | AF8: 1 | AG8: 23 | AH8: 2 | AI8: 1
A9: Probe: did participant fail probe - 1 = yes, 0 = no (to be completed | D9: 120073 | E9: 2 | F9: 2 | G9: 21 | H9: 0 | I9: 3 | AA9: 0 | AB9: 60 | AC9: 0 | AF9: 1 | AG9: 20 | AH9: 1 | AI9: 1
A10: by two independent coders AFTER termination of data collection) | D10: 122535 | E10: 1 | F10: 1 | Q10: 0 | R10: 1 | S10: 0 | AA10: 0 | AB10: 40 | AC10: 0 | AF10: 2 | AG10: 22 | AH10: 1 | AI10: 1
A11: MC = manipulation check (think = 1, not think = 2) | D11: 128377 | E11: 2 | F11: 1 | G11: 23 | H11: 7 | I11: 9 | AA11: 0 | AB11: 60 | AC11: 0 | AF11: 1 | AG11: 23 | AH11: 2 | AI11: 1
A12: Gender: female = 1, male = 2, other = 3, prefer not to say = 4 | D12: 143217 | E12: 2 | F12: 4 | G12: 37 | H12: 3 | I12: 2 | AA12: 85 | AB12: 87 | AC12: 0 | AF12: 1 | AG12: 22 | AH12: 1 | AI12: 1
A13: Compliance: complied with experimental instructions? Yes = 1, No = 2 | D13: 155583 | E13: 2 | F13: 1 | G13: 35 | H13: 3 | I13: 4 | AA13: 0 | AB13: 70 | AC13: 0 | AF13: 1 | AG13: 19 | AH13: 1 | AI13: 1
D14: 160903 | E14: 2 | F14: 4 | G14: 27 | H14: 0 | I14: 8 | AA14: 0 | AB14: 90 | AC14: 0 | AF14: 1 | AG14: 20 | AH14: 1 | AI14: 1
A15: not think = 1 | D15: 170171 | E15: 1 | F15: 4 | Q15: 0 | R15: 2 | S15: 0 | AA15: 0 | AB15: 40 | AC15: 1 | AF15: 1 | AG15: 19 | AH15: 1 | AI15: 1
A16: think =2 | D16: 194097 | E16: 2 | F16: 1 | G16: 6 | H16: 11 | I16: 12 | AA16: 0 | AB16: 80 | AC16: 0 | AF16: 1 | AG16: 20 | AH16: 1 | AI16: 1
D17: 197532 | E17: 2 | F17: 4 | G17: 22 | H17: 0 | I17: 7 | AA17: 0 | AB17: 90 | AC17: 0 | AF17: 1 | AG17: 21 | AH17: 1 | AI17: 1
A18: =ROWS(D6:D126) -> 121 | D18: 197689 | E18: 1 | F18: 3 | Q18: 0 | R18: 0 | S18: 1 | AA18: 2 | AB18: 65 | AC18: 0 | AF18: 1 | AG18: 23 | AH18: 1 | AI18: 2
D19: 199134 | E19: 1 | F19: 3 | Q19: 2 | R19: 2 | S19: 1 | AA19: 50 | AB19: 20 | AC19: 1 | AF19: 2 | AG19: 20 | AH19: 1 | AI19: 1
D20: 203165 | E20: 1 | F20: 2 | Q20: 2 | R20: 3 | S20: 8 | AA20: 0 | AB20: 20 | AC20: 1 | AF20: 2 | AG20: 18 | AH20: 1 | AI20: 1
D21: 205813 | E21: 1 | F21: 1 | Q21: 1 | R21: 1 | S21: 1 | AA21: 0 | AB21: 2 | AC21: 1 | AF21: 2 | AG21: 19 | AH21: 1 | AI21: 1
D22: 215393 | E22: 1 | F22: 3 | Q22: 0 | R22: 12 | S22: 0 | AA22: 0 | AB22: 40 | AC22: 1 | AF22: 2 | AG22: 19 | AH22: 1 | AI22: 1
D23: 222449 | E23: 1 | F23: 1 | Q23: 0 | R23: 2 | S23: 0 | AA23: 0 | AB23: 20 | AC23: 1 | AF23: 2 | AG23: 19 | AH23: 1 | AI23: 1
D24: 224807 | E24: 1 | F24: 2 | Q24: 1 | R24: 7 | S24: 1 | AA24: 0 | AB24: 20 | AC24: 1 | AF24: 2 | AG24: 23 | AH24: 2 | AI24: 1
D25: 243885 | E25: 1 | F25: 3 | Q25: 0 | R25: 1 | S25: 0 | AA25: 90 | AB25: 100 | AC25: 1 | AF25: 2 | AG25: 19 | AH25: 1 | AI25: 1
D26: 250971 | E26: 1 | F26: 2 | Q26: 0 | R26: 2 | S26: 1 | AA26: 0 | AB26: 10 | AC26: 1 | AF26: 2 | AG26: 18 | AH26: 1 | AI26: 1
D27: 256240 | E27: 2 | F27: 3 | G27: 9 | H27: 25 | I27: 21 | AA27: 5 | AB27: 90 | AC27: 0 | AF27: 1 | AG27: 25 | AH27: 2 | AI27: 1
D28: 262983 | E28: 2 | F28: 2 | G28: 5 | H28: 2 | I28: 3 | AA28: 0 | AB28: 40 | AC28: 0 | AF28: 1 | AG28: 19 | AH28: 1 | AI28: 1
D29: 264413 | E29: 2 | F29: 3 | G29: 25 | H29: 3 | I29: 15 | AA29: 10 | AB29: 90 | AC29: 0 | AF29: 1 | AG29: 19 | AH29: 1 | AI29: 1
D30: 265388 | E30: 2 | F30: 3 | G30: 23 | H30: 0 | I30: 10 | AA30: 0 | AB30: 100 | AC30: 0 | AF30: 1 | AG30: 21 | AH30: 1 | AI30: 1
D31: 277194 | E31: 1 | F31: 1 | Q31: 0 | R31: 5 | S31: 0 | AA31: 0 | AB31: 20 | AC31: 1 | AF31: 2 | AG31: 21 | AH31: 1 | AI31: 1
D32: 310918 | E32: 2 | F32: 4 | G32: 25 | H32: 4 | I32: 6 | AA32: 0 | AB32: 70 | AC32: 0 | AF32: 1 | AG32: 22 | AH32: 2 | AI32: 1
D33: 315045 | E33: 1 | F33: 3 | AA33: 10 | AB33: 20 | AF33: 2 | AG33: 21 | AH33: 1 | AI33: 1
D34: 326586 | E34: 1 | F34: 2 | G34: 0 | H34: 2 | I34: 1 | AA34: 0 | AB34: 20 | AC34: 1 | AF34: 2 | AG34: 21 | AH34: 1 | AI34: 1
D35: 330133 | E35: 2 | F35: 3 | Q35: 15 | R35: 7 | S35: 19 | AA35: 15 | AB35: 90 | AC35: 0 | AF35: 1 | AG35: 29 | AH35: 2 | AI35: 1
D36: 341963 | E36: 2 | F36: 4 | Q36: 4 | R36: 1 | S36: 14 | AA36: 0 | AB36: 80 | AC36: 0 | AF36: 1 | AG36: 21 | AH36: 1 | AI36: 1
D37: 352082 | E37: 1 | F37: 1 | Q37: 0 | R37: 8 | S37: 8 | AA37: 0 | AB37: 20 | AC37: 1 | AF37: 2 | AG37: 20 | AH37: 1 | AI37: 1
D38: 354902 | E38: 2 | F38: 2 | G38: 0 | H38: 8 | I38: 0 | AA38: 0 | AB38: 10 | AC38: 0 | AF38: 1 | AG38: 20 | AH38: 1 | AI38: 1
D39: 367470 | E39: 1 | F39: 1 | Q39: 0 | R39: 3 | S39: 2 | AA39: 0 | AB39: 2 | AC39: 1 | AF39: 2 | AG39: 22 | AH39: 1 | AI39: 1
D40: 377404 | E40: 1 | F40: 2 | Q40: 0 | R40: 14 | S40: 2 | T40: 0 | U40: 14 | V40: 2 | AA40: 0 | AB40: 60 | AC40: 1 | AF40: 2 | AG40: 23 | AH40: 1 | AI40: 1
...

Sheet Noelle (before resolving)
A1: Notes: | D1: ParticipantID | E1: Condition | F1: Targetword | G1: A_period.1.coder1 | H1: B_period.1.coder1 | I1: C_period.1.coder1 | J1: A_period.1.coder2 | K1: B_period.1.coder2 | L1: C_period.1.coder2 | M1: A_period.1.final | N1: B_period.1.final | O1: C_period.1.final | P1: sum.of.ABC_period.1.final | Q1: A_period.2.coder1 | R1: B_period.2.coder1 | S1: C_period.2.coder1 | T1: A_period.2.coder2 | U1: B_period.2.coder2 | V1: C_period.2.coder2 | W1: A_period.2.final | X1: B_period.2.final | Y1: C_period.2.final | Z1: sum.ABC_period2.final | AA1: Percentage.round.1 | AB1: Percentage.round.2 | AC1: probe.coder1 | AD1: probe.coder2 | AE1: probe.final | AF1: MC | AG1: age | AH1: gender | AI1: Compliance
A2: Condition (initial suppression = 1, initial concentration = 2) | C2: Example | D2: 1001 | E2: 1 | F2: 1 | G2: 18 | H2: 4 | I2: 8 | J2: 18 | K2: 4 | L2: 8 | M2: 18 | N2: 4 | O2: 8 | P2: =SUM(M2,Q2,N2,O2) -> 44 | Q2: 14 | R2: 15 | S2: 20 | T2: 14 | U2: 15 | V2: 20 | W2: 14 | X2: 15 | Y2: 20 | Z2: =SUM(W2,X2,Y2) -> 49 | AC2: 0 | AD2: 0 | AE2: 0 | AF2: 1 | AG2: 30 | AH2: 1 | AI2: 1
A3: Target word (gorilla = 1, tiger = 2, food = 3, diseases = 4) | D3: 1002 | E3: 1 | F3: 2 | G3: 18 | H3: 16 | I3: 16 | J3: 18 | K3: 16 | L3: 16 | M3: 18 | N3: 16 | O3: 16 | P3: =SUM(M3,Q3,N3,O3) -> 63 | Q3: 13 | R3: 16 | S3: 15 | T3: 13 | U3: 16 | V3: 15 | W3: 13 | X3: 16 | Y3: 15 | Z3: =SUM(W3,X3,Y3) -> 44 | AC3: 0 | AD3: 1 | AE3: 0 | AF3: 1 | AG3: 25 | AH3: 1 | AI3: 1
A4: Participant ID should start from 121 rather than 001 | D4: 1003 | E4: 2 | F4: 3 | G4: 2 | H4: 3 | I4: 19 | J4: 2 | K4: 3 | L4: 19 | M4: 2 | N4: 3 | O4: 19 | P4: =SUM(M4,Q4,N4,O4) -> 37 | Q4: 13 | R4: 3 | S4: 5 | T4: 13 | U4: 3 | V4: 5 | W4: 13 | X4: 3 | Y4: 5 | Z4: =SUM(W4,X4,Y4) -> 21 | AC4: 0 | AD4: 0 | AE4: 0 | AF4: 2 | AG4: 26 | AH4: 2 | AI4: 1
A5: A = number of target thought mentions only, B = number of bell rings only, C = number of thought mentions and bell rings at the same time | D5: 1004 | E5: 2 | F5: 4 | G5: 20 | H5: 13 | I5: 2 | J5: 20 | K5: 13 | L5: 2 | M5: 20 | N5: 13 | O5: 2 | P5: =SUM(M5,Q5,N5,O5) -> 43 | Q5: 8 | R5: 14 | S5: 12 | T5: 8 | U5: 14 | V5: 12 | W5: 8 | X5: 14 | Y5: 12 | Z5: =SUM(W5,X5,Y5) -> 34 | AC5: 1 | AD5: 1 | AE5: 1 | AF5: 2 | AG5: 18 | AH5: 2 | AI5: 1
A6: Period 1 only needs to be completed for initial concentration group | C6: Start data entry here from 1 onwards | D6: 100161 | E6: 1 | F6: 1 | Q6: 0 | R6: 0 | S6: 0 | AA6: 0 | AB6: 1 | AC6: 0 | AF6: 2 | AG6: 20 | AH6: 1 | AI6: 1
A7: Final = results after resolving any inter-coder discrepancies | D7: 104496 | E7: 1 | F7: 2 | Q7: 0 | R7: 0 | S7: 0 | AA7: 0 | AB7: 10 | AC7: 0 | AF7: 1 | AG7: 19 | AH7: 1 | AI7: 1
A8: Percentage = % time participant indicate to be thinking about target thought | D8: 117872 | E8: 2 | F8: 2 | G8: 20 | H8: 7 | I8: 14 | J8: 20 | K8: 7 | L8: 14 | AA8: 0 | AB8: 60 | AC8: 0 | AF8: 1 | AG8: 23 | AH8: 2 | AI8: 1
A9: Probe: did participant fail probe - 1 = yes, 0 = no (to be completed | D9: 120073 | E9: 2 | F9: 2 | G9: 21 | H9: 0 | I9: 3 | J9: 21 | K9: 0 | L9: 3 | AA9: 0 | AB9: 60 | AC9: 0 | AF9: 1 | AG9: 20 | AH9: 1 | AI9: 1
A10: by two independent coders AFTER termination of data collection) | D10: 122535 | E10: 1 | F10: 1 | Q10: 0 | R10: 1 | S10: 0 | AA10: 0 | AB10: 40 | AC10: 0 | AF10: 2 | AG10: 22 | AH10: 1 | AI10: 1
A11: MC = manipulation check (think = 1, not think = 2) | D11: 128377 | E11: 2 | F11: 1 | G11: 23 | H11: 7 | I11: 9 | J11: 23 | K11: 7 | L11: 9 | AA11: 0 | AB11: 60 | AC11: 0 | AF11: 1 | AG11: 23 | AH11: 2 | AI11: 1
A12: Gender: female = 1, male = 2, other = 3, prefer not to say = 4 | D12: 143217 | E12: 2 | F12: 4 | G12: 37 | H12: 3 | I12: 2 | J12: 37 | K12: 3 | L12: 2 | AA12: 85 | AB12: 87 | AC12: 0 | AF12: 1 | AG12: 22 | AH12: 1 | AI12: 1
A13: Compliance: complied with experimental instructions? Yes = 1, No = 2 | D13: 155583 | E13: 2 | F13: 1 | G13: 35 | H13: 3 | I13: 4 | J13: 35 | K13: 3 | L13: 4 | AA13: 0 | AB13: 70 | AC13: 0 | AF13: 1 | AG13: 19 | AH13: 1 | AI13: 1
D14: 160903 | E14: 2 | F14: 4 | G14: 27 | H14: 0 | I14: 8 | J14: 27 | K14: 0 | L14: 8 | AA14: 0 | AB14: 90 | AC14: 0 | AF14: 1 | AG14: 20 | AH14: 1 | AI14: 1
A15: not think = 1 | D15: 170171 | E15: 1 | F15: 4 | Q15: 0 | R15: 2 | S15: 0 | AA15: 0 | AB15: 40 | AC15: 1 | AF15: 1 | AG15: 19 | AH15: 1 | AI15: 1
A16: think =2 | D16: 194097 | E16: 2 | F16: 1 | G16: 6 | H16: 11 | I16: 12 | J16: 6 | K16: 11 | L16: 12 | AA16: 0 | AB16: 80 | AC16: 0 | AF16: 1 | AG16: 20 | AH16: 1 | AI16: 1
D17: 197532 | E17: 2 | F17: 4 | G17: 22 | H17: 0 | I17: 7 | J17: 22 | K17: 0 | L17: 7 | AA17: 0 | AB17: 90 | AC17: 0 | AF17: 1 | AG17: 21 | AH17: 1 | AI17: 1
A18: =ROWS(D6:D126) -> 121 | D18: 197689 | E18: 1 | F18: 3 | Q18: 0 | R18: 0 | S18: 1 | AA18: 2 | AB18: 65 | AC18: 0 | AF18: 1 | AG18: 23 | AH18: 1 | AI18: 2
D19: 199134 | E19: 1 | F19: 3 | Q19: 2 | R19: 2 | S19: 1 | AA19: 50 | AB19: 20 | AC19: 1 | AF19: 2 | AG19: 20 | AH19: 1 | AI19: 1
D20: 203165 | E20: 1 | F20: 2 | Q20: 2 | R20: 3 | S20: 8 | AA20: 0 | AB20: 20 | AC20: 1 | AF20: 2 | AG20: 18 | AH20: 1 | AI20: 1
D21: 205813 | E21: 1 | F21: 1 | Q21: 1 | R21: 1 | S21: 1 | AA21: 0 | AB21: 80 | AC21: 1 | AF21: 2 | AG21: 19 | AH21: 1 | AI21: 1
D22: 215393 | E22: 1 | F22: 3 | Q22: 0 | R22: 12 | S22: 0 | AA22: 0 | AB22: 40 | AC22: 1 | AF22: 2 | AG22: 19 | AH22: 1 | AI22: 1
D23: 222449 | E23: 1 | F23: 1 | Q23: 0 | R23: 2 | S23: 0 | AA23: 0 | AB23: 20 | AC23: 1 | AF23: 2 | AG23: 19 | AH23: 1 | AI23: 1
D24: 224807 | E24: 1 | F24: 2 | Q24: 1 | R24: 7 | S24: 1 | AA24: 0 | AB24: 20 | AC24: 1 | AF24: 2 | AG24: 23 | AH24: 2 | AI24: 1
D25: 243885 | E25: 1 | F25: 3 | Q25: 0 | R25: 1 | S25: 0 | AA25: 90 | AB25: 100 | AC25: 1 | AF25: 2 | AG25: 19 | AH25: 1 | AI25: 1
D26: 250971 | E26: 1 | F26: 2 | Q26: 0 | R26: 2 | S26: 1 | AA26: 0 | AB26: 10 | AC26: 1 | AF26: 2 | AG26: 18 | AH26: 1 | AI26: 1
D27: 256240 | E27: 2 | F27: 3 | G27: 9 | H27: 25 | I27: 21 | J27: 9 | K27: 25 | L27: 21 | AA27: 5 | AB27: 90 | AC27: 0 | AF27: 1 | AG27: 25 | AH27: 2 | AI27: 1
D28: 262983 | E28: 2 | F28: 2 | G28: 5 | H28: 2 | I28: 3 | J28: 5 | K28: 2 | L28: 3 | AA28: 0 | AB28: 40 | AC28: 0 | AF28: 1 | AG28: 19 | AH28: 1 | AI28: 1
D29: 264413 | E29: 2 | F29: 3 | G29: 25 | H29: 3 | I29: 15 | J29: 25 | K29: 3 | L29: 15 | AA29: 10 | AB29: 90 | AC29: 0 | AF29: 1 | AG29: 19 | AH29: 1 | AI29: 1
D30: 265388 | E30: 2 | F30: 3 | G30: 23 | H30: 0 | I30: 10 | J30: 23 | K30: 0 | L30: 10 | AA30: 0 | AB30: 100 | AC30: 0 | AF30: 1 | AG30: 21 | AH30: 1 | AI30: 1
D31: 277194 | E31: 1 | F31: 1 | Q31: 0 | R31: 5 | S31: 0 | AA31: 0 | AB31: 20 | AC31: 1 | AF31: 2 | AG31: 21 | AH31: 1 | AI31: 1
D32: 310918 | E32: 2 | F32: 4 | G32: 25 | H32: 4 | I32: 6 | J32: 25 | K32: 4 | L32: 6 | AA32: 0 | AB32: 70 | AC32: 0 | AF32: 1 | AG32: 22 | AH32: 2 | AI32: 1
D33: 315045 | E33: 1 | F33: 3 | G33: 2 | H33: 2 | I33: 1 | J33: 2 | K33: 2 | L33: 1 | AA33: 10 | AB33: 20 | AC33: 0 | AF33: 2 | AG33: 21 | AH33: 1 | AI33: 1
D34: 326586 | E34: 1 | F34: 2 | Q34: 0 | R34: 2 | S34: 1 | AA34: 0 | AB34: 20 | AC34: 1 | AF34: 2 | AG34: 21 | AH34: 1 | AI34: 1
D35: 330133 | E35: 2 | F35: 3 | G35: 15 | H35: 7 | I35: 19 | J35: 15 | K35: 7 | L35: 19 | AA35: 15 | AB35: 90 | AC35: 0 | AF35: 1 | AG35: 29 | AH35: 2 | AI35: 1
D36: 341963 | E36: 2 | F36: 4 | G36: 4 | H36: 1 | I36: 14 | J36: 4 | K36: 1 | L36: 14 | AA36: 0 | AB36: 80 | AC36: 0 | AF36: 1 | AG36: 21 | AH36: 1 | AI36: 1
D37: 352082 | E37: 1 | F37: 1 | Q37: 0 | R37: 8 | S37: 8 | AA37: 0 | AB37: 20 | AC37: 1 | AF37: 2 | AG37: 20 | AH37: 1 | AI37: 1
D38: 354902 | E38: 2 | F38: 2 | G38: 0 | H38: 8 | I38: 0 | J38: 0 | K38: 8 | L38: 0 | AA38: 0 | AB38: 10 | AC38: 0 | AF38: 2 | AG38: 20 | AH38: 1 | AI38: 1
D39: 367470 | E39: 1 | F39: 1 | Q39: 0 | R39: 3 | S39: 2 | AA39: 0 | AB39: 2 | AC39: 1 | AF39: 2 | AG39: 22 | AH39: 1 | AI39: 1
D40: 377404 | E40: 1 | F40: 2 | Q40: 0 | R40: 14 | S40: 2 | AA40: 0 | AB40: 60 | AC40: 1 | AF40: 2 | AG40: 23 | AH40: 1 | AI40: 1
...

Sheet Meilan (resolving)
A1: Notes: | D1: ParticipantID | E1: Condition | F1: Targetword | G1: A_period.1.coder1 | H1: B_period.1.coder1 | I1: C_period.1.coder1 | J1: A_period.1.coder2 | K1: B_period.1.coder2 | L1: C_period.1.coder2 | M1: A_period.1.final | N1: B_period.1.final | O1: C_period.1.final | P1: sum.of.ABC_period.1.final | Q1: A_period.2.coder1 | R1: B_period.2.coder1 | S1: C_period.2.coder1 | T1: A_period.2.coder2 | U1: B_period.2.coder2 | V1: C_period.2.coder2 | W1: A_period.2.final | X1: B_period.2.final | Y1: C_period.2.final | Z1: sum.ABC_period2.final | AA1: Percentage.round.1 | AB1: Percentage.round.2 | AC1: probe.coder1 | AD1: probe.coder2 | AE1: probe.final | AF1: MC | AG1: age | AH1: gender | AI1: Compliance
A2: Condition (initial suppression = 1, initial concentration = 2) | C2: Example | D2: 1001 | E2: 1 | F2: 1 | G2: 18 | H2: 4 | I2: 8 | J2: 18 | K2: 4 | L2: 8 | M2: 18 | N2: 4 | O2: 8 | P2: =SUM(M2,Q2,N2,O2) -> 44 | Q2: 14 | R2: 15 | S2: 20 | T2: 14 | U2: 15 | V2: 20 | W2: 14 | X2: 15 | Y2: 20 | Z2: =SUM(W2,X2,Y2) -> 49 | AC2: 0 | AD2: 0 | AE2: 0 | AF2: 1 (think) | AG2: 30 | AH2: 1 | AI2: 1 (yes)
A3: Target word (gorilla = 1, tiger = 2, food = 3, diseases = 4) | D3: 1002 | E3: 1 | F3: 2 | G3: 18 | H3: 16 | I3: 16 | J3: 18 | K3: 16 | L3: 16 | M3: 18 | N3: 16 | O3: 16 | P3: =SUM(M3,Q3,N3,O3) -> 63 | Q3: 13 | R3: 16 | S3: 15 | T3: 13 | U3: 16 | V3: 15 | W3: 13 | X3: 16 | Y3: 15 | Z3: =SUM(W3,X3,Y3) -> 44 | AC3: 0 | AD3: 1 | AE3: 0 | AF3: 1 | AG3: 25 | AH3: 1 | AI3: 1
A4: Participant ID should start from 121 rather than 001 | D4: 1003 | E4: 2 | F4: 3 | G4: 2 | H4: 3 | I4: 19 | J4: 2 | K4: 3 | L4: 19 | M4: 2 | N4: 3 | O4: 19 | P4: =SUM(M4,Q4,N4,O4) -> 37 | Q4: 13 | R4: 3 | S4: 5 | T4: 13 | U4: 3 | V4: 5 | W4: 13 | X4: 3 | Y4: 5 | Z4: =SUM(W4,X4,Y4) -> 21 | AC4: 0 | AD4: 0 | AE4: 0 | AF4: 2 (not think) | AG4: 26 | AH4: 2 | AI4: 1
A5: A = number of target thought mentions only, B = number of bell rings only, C = number of thought mentions and bell rings at the same time | D5: 1004 | E5: 2 | F5: 4 | G5: 20 | H5: 13 | I5: 2 | J5: 20 | K5: 13 | L5: 2 | M5: 20 | N5: 13 | O5: 2 | P5: =SUM(M5,Q5,N5,O5) -> 43 | Q5: 8 | R5: 14 | S5: 12 | T5: 8 | U5: 14 | V5: 12 | W5: 8 | X5: 14 | Y5: 12 | Z5: =SUM(W5,X5,Y5) -> 34 | AC5: 1 | AD5: 1 | AE5: 1 | AF5: 2 | AG5: 18 | AH5: 2 | AI5: 1
A6: Period 1 only needs to be completed for initial concentration group | C6: Start data entry here from 1 onwards | D6: 100161 | E6: 1 | F6: 1 | T6: 0 | U6: 0 | V6: 0 | AA6: 0 | AB6: 1 | AD6: 0 | AF6: 2 | AG6: 20 | AH6: 1 | AI6: 1
A7: Final = results after resolving any inter-coder discrepancies | D7: 104496 | E7: 1 | F7: 2 | T7: 0 | U7: 0 | V7: 0 | AA7: 0 | AB7: 10 | AD7: 0 | AF7: 1 | AG7: 19 | AH7: 1 | AI7: 1
A8: Percentage = % time participant indicate to be thinking about target thought | D8: 117872 | E8: 2 | F8: 2 | J8: 24 | K8: 5 | L8: 12 | AA8: 0 | AB8: 60 | AD8: 0 | AF8: 1 | AG8: 23 | AH8: 2 | AI8: 1
A9: Probe: did participant fail probe - 1 = yes, 0 = no (to be completed | D9: 120073 | E9: 2 | F9: 2 | J9: 16 | K9: 0 | L9: 3 | AA9: 0 | AB9: 60 | AD9: 0 | AF9: 1 | AG9: 20 | AH9: 1 | AI9: 1
A10: by two independent coders AFTER termination of data collection) | D10: 122535 | E10: 1 | F10: 1 | T10: 0 | U10: 3 | V10: 0 | AA10: 0 | AB10: 40 | AD10: 1 | AF10: 2 | AG10: 22 | AH10: 1 | AI10: 1
A11: MC = manipulation check (think = 1, not think = 2) | D11: 128377 | E11: 2 | F11: 1 | J11: 21 | K11: 4 | L11: 6 | AA11: 0 | AB11: 60 | AD11: 0 | AF11: 1 | AG11: 23 | AH11: 2 | AI11: 1
A12: Gender: female = 1, male = 2, other = 3, prefer not to say = 4 | D12: 143217 | E12: 2 | F12: 4 | J12: 33 | K12: 1 | L12: 5 | AA12: 85 | AB12: 87 | AD12: 0 | AF12: 1 | AG12: 22 | AH12: 1 | AI12: 1
A13: Compliance: complied with experimental instructions? Yes = 1, No = 2 | D13: 155583 | E13: 2 | F13: 1 | J13: 28 | K13: 4 | L13: 5 | AA13: 0 | AB13: 70 | AD13: 0 | AF13: 1 | AG13: 19 | AH13: 1 | AI13: 1
D14: 160903 | E14: 2 | F14: 4 | J14: 26 | K14: 0 | L14: 7 | AA14: 0 | AB14: 90 | AD14: 0 | AF14: 1 | AG14: 20 | AH14: 1 | AI14: 1
D15: 170171 | E15: 1 | F15: 4 | T15: 0 | U15: 4 | V15: 0 | AA15: 0 | AB15: 40 | AD15: 1 | AF15: 1 | AG15: 19 | AH15: 1 | AI15: 1
D16: 194097 | E16: 2 | F16: 1 | J16: 9 | K16: 9 | L16: 8 | AA16: 0 | AB16: 80 | AD16: 0 | AF16: 1 | AG16: 20 | AH16: 1 | AI16: 1
D17: 197532 | E17: 2 | F17: 4 | J17: 12 | K17: 0 | L17: 9 | AA17: 0 | AB17: 90 | AD17: 0 | AF17: 1 | AG17: 21 | AH17: 1 | AI17: 1
D18: 197689 | E18: 1 | F18: 3 | T18: 1 | U18: 7 | V18: 0 | AA18: 2 | AB18: 65 | AD18: 1 | AF18: 1 | AG18: 23 | AH18: 1 | AI18: 2
D19: 199134 | E19: 1 | F19: 3 | T19: 0 | U19: 3 | V19: 1 | AA19: 50 | AB19: 20 | AD19: 1 | AF19: 2 | AG19: 20 | AH19: 1 | AI19: 1
D20: 203165 | E20: 1 | F20: 2 | T20: 3 | U20: 4 | V20: 7 | AA20: 0 | AB20: 20 | AD20: 1 | AF20: 2 | AG20: 18 | AH20: 1 | AI20: 1
D21: 205813 | E21: 1 | F21: 1 | T21: 2 | U21: 3 | V21: 0 | AA21: 0 | AB21: 2 | AD21: 1 | AF21: 2 | AG21: 19 | AH21: 1 | AI21: 1
D22: 215393 | E22: 1 | F22: 3 | T22: 0 | U22: 8 | V22: 2 | AA22: 0 | AB22: 40 | AD22: 1 | AF22: 2 | AG22: 19 | AH22: 1 | AI22: 1
D23: 222449 | E23: 1 | F23: 1 | T23: 0 | U23: 0 | V23: 0 | AA23: 0 | AB23: 20 | AD23: 0 | AF23: 2 | AG23: 19 | AH23: 1 | AI23: 1
D24: 224807 | E24: 1 | F24: 2 | T24: 0 | U24: 0 | V24: 0 | AA24: 0 | AB24: 20 | AD24: 0 | AF24: 2 | AG24: 23 | AH24: 2 | AI24: 1
D25: 243885 | E25: 1 | F25: 3 | T25: 0 | U25: 0 | V25: 0 | AA25: 90 | AB25: 100 | AD25: 0 | AF25: 2 | AG25: 19 | AH25: 1 | AI25: 1
D26: 250971 | E26: 1 | F26: 2 | T26: 0 | U26: 2 | V26: 3 | AA26: 0 | AB26: 10 | AD26: 1 | AF26: 2 | AG26: 18 | AH26: 1 | AI26: 1
D27: 256240 | E27: 2 | F27: 3 | J27: 7 | K27: 20 | L27: 23 | AA27: 5 | AB27: 90 | AD27: 0 | AF27: 1 | AG27: 25 | AH27: 2 | AI27: 1
D28: 262983 | E28: 2 | F28: 2 | J28: 3 | K28: 2 | L28: 3 | AA28: 0 | AB28: 40 | AD28: 0 | AF28: 1 | AG28: 19 | AH28: 1 | AI28: 1
D29: 264413 | E29: 2 | F29: 3 | J29: 11 | K29: 5 | L29: 10 | AA29: 10 | AB29: 90 | AD29: 0 | AF29: 1 | AG29: 19 | AH29: 1 | AI29: 1
D30: 265399 | E30: 2 | F30: 3 | J30: 28 | K30: 1 | L30: 8 | AA30: 0 | AB30: 100 | AD30: 0 | AF30: 1 | AG30: 21 | AH30: 1 | AI30: 1
D31: 277194 | E31: 1 | F31: 1 | T31: 0 | U31: 2 | V31: 0 | AA31: 0 | AB31: 20 | AD31: 1 | AF31: 2 | AG31: 21 | AH31: 1 | AI31: 1
D32: 310918 | E32: 2 | F32: 4 | J32: 21 | K32: 6 | L32: 1 | AA32: 0 | AB32: 70 | AD32: 0 | AF32: 1 | AG32: 22 | AH32: 2 | AI32: 1
D33: 315045 | E33: 1 | F33: 3 | T33: 1 | U33: 3 | V33: 1 | AA33: 10 | AB33: 20 | AD33: 0 | AF33: 2 | AG33: 21 | AH33: 1 | AI33: 1
D34: 326586 | E34: 1 | F34: 2 | T34: 0 | U34: 2 | V34: 1 | AA34: 0 | AB34: 20 | AD34: 1 | AF34: 2 | AG34: 21 | AH34: 1 | AI34: 1
D35: 330133 | E35: 2 | F35: 3 | J35: 18 | K35: 0 | L35: 4 | AA35: 15 | AB35: 90 | AD35: 0 | AF35: 1 | AG35: 29 | AH35: 2 | AI35: 1
D36: 341963 | E36: 2 | F36: 4 | J36: 5 | K36: 0 | L36: 12 | AA36: 0 | AB36: 80 | AD36: 0 | AF36: 1 | AG36: 21 | AH36: 1 | AI36: 1
D37: 352082 | E37: 1 | F37: 1 | T37: 4 | U37: 1 | V37: 4 | AA37: 0 | AB37: 20 | AD37: 1 | AF37: 2 | AG37: 20 | AH37: 1 | AI37: 1
D38: 354902 | E38: 2 | F38: 2 | J38: 0 | K38: 3 | L38: 1 | AA38: 0 | AB38: 10 | AD38: 0 | AF38: 1 | AG38: 20 | AH38: 1 | AI38: 1
D39: 367470 | E39: 1 | F39: 1 | T39: 0 | U39: 0 | V39: 2 | AA39: 0 | AB39: 2 | AD39: 1 | AF39: 2 | AG39: 22 | AH39: 1 | AI39: 1
D40: 377404 | E40: 1 | F40: 2 | T40: 2 | U40: 5 | V40: 0 | AA40: 0 | AB40: 60 | AD40: 1 | AF40: 2 | AG40: 23 | AH40: 1 | AI40: 1
...

Sheet Resolved
A1: Notes: | D1: ParticipantID | E1: Condition | F1: Targetword | G1: A_period.1.coder1 | H1: B_period.1.coder1 | I1: C_period.1.coder1 | J1: A_period.1.coder2 | K1: B_period.1.coder2 | L1: C_period.1.coder2 | M1: A_period.1.final | N1: B_period.1.final | O1: C_period.1.final | P1: sum.of.ABC_period.1.final | Q1: A_period.2.coder1 | R1: B_period.2.coder1 | S1: C_period.2.coder1 | T1: A_period.2.coder2 | U1: B_period.2.coder2 | V1: C_period.2.coder2 | W1: A_period.2.final | X1: B_period.2.final | Y1: C_period.2.final | Z1: sum.ABC_period2.final | AA1: Percentage.round.1 | AB1: Percentage.round.2 | AC1: probe.coder1 | AD1: probe.coder2 | AE1: probe.final | AF1: MC | AG1: age | AH1: gender | AI1: Compliance
A2: Condition (initial suppression = 1, initial concentration = 2) | C2: Example | D2: 1001 | E2: 1 | F2: 1 | G2: 18 | H2: 4 | I2: 8 | J2: 18 | K2: 4 | L2: 8 | M2: 18 | N2: 4 | O2: 8 | P2: =SUM(M2,Q2,N2,O2) -> 44 | Q2: 14 | R2: 15 | S2: 20 | T2: 14 | U2: 15 | V2: 20 | W2: 14 | X2: 15 | Y2: 20 | Z2: =SUM(W2,X2,Y2) -> 49 | AC2: 0 | AD2: 0 | AE2: 0 | AF2: 1 (think) | AG2: 30 | AH2: 1 | AI2: 1 (yes)
A3: Target word (gorilla = 1, tiger = 2, food = 3, diseases = 4) | D3: 1002 | E3: 1 | F3: 2 | G3: 18 | H3: 16 | I3: 16 | J3: 18 | K3: 16 | L3: 16 | M3: 18 | N3: 16 | O3: 16 | P3: =SUM(M3,Q3,N3,O3) -> 63 | Q3: 13 | R3: 16 | S3: 15 | T3: 13 | U3: 16 | V3: 15 | W3: 13 | X3: 16 | Y3: 15 | Z3: =SUM(W3,X3,Y3) -> 44 | AC3: 0 | AD3: 1 | AE3: 0 | AF3: 1 | AG3: 25 | AH3: 1 | AI3: 1
A4: Participant ID should start from 121 rather than 001 | D4: 1003 | E4: 2 | F4: 3 | G4: 2 | H4: 3 | I4: 19 | J4: 2 | K4: 3 | L4: 19 | M4: 2 | N4: 3 | O4: 19 | P4: =SUM(M4,Q4,N4,O4) -> 37 | Q4: 13 | R4: 3 | S4: 5 | T4: 13 | U4: 3 | V4: 5 | W4: 13 | X4: 3 | Y4: 5 | Z4: =SUM(W4,X4,Y4) -> 21 | AC4: 0 | AD4: 0 | AE4: 0 | AF4: 2 (not think) | AG4: 26 | AH4: 2 | AI4: 1
A5: A = number of target thought mentions only, B = number of bell rings only, C = number of thought mentions and bell rings at the same time | D5: 1004 | E5: 2 | F5: 4 | G5: 20 | H5: 13 | I5: 2 | J5: 20 | K5: 13 | L5: 2 | M5: 20 | N5: 13 | O5: 2 | P5: =SUM(M5,Q5,N5,O5) -> 43 | Q5: 8 | R5: 14 | S5: 12 | T5: 8 | U5: 14 | V5: 12 | W5: 8 | X5: 14 | Y5: 12 | Z5: =SUM(W5,X5,Y5) -> 34 | AC5: 1 | AD5: 1 | AE5: 1 | AF5: 2 | AG5: 18 | AH5: 2 | AI5: 1
A6: Period 1 only needs to be completed for initial concentration group | C6: Start data entry here from 1 onwards | D6: 100161 | E6: 1 | F6: 1 | Q6: 0 | R6: 0 | S6: 0 | T6: 0 | U6: 0 | V6: 0 | W6: 0 | X6: 0 | Y6: 0 | Z6: =SUM(W6:Y6) -> 0 | AA6: 0 | AB6: 1 | AC6: 0 | AD6: 0 | AE6: 0 | AF6: 2 | AG6: 20 | AH6: 1 | AI6: 1
A7: Final = results after resolving any inter-coder discrepancies | D7: 104496 | E7: 1 | F7: 2 | Q7: 0 | R7: 0 | S7: 0 | T7: 0 | U7: 0 | V7: 0 | W7: 0 | X7: 0 | Y7: 0 | Z7: =SUM(W7:Y7) -> 0 | AA7: 0 | AB7: 10 | AC7: 0 | AD7: 0 | AE7: 0 | AF7: 1 | AG7: 19 | AH7: 1 | AI7: 1
A8: Percentage = % time participant indicate to be thinking about target thought | D8: 117872 | E8: 2 | F8: 2 | G8: 20 | H8: 7 | I8: 14 | J8: 24 | K8: 5 | L8: 12 | M8: 24 | N8: 5 | O8: 12 | P8: =SUM(L8:O8) -> 53 | Q8: 20 | R8: 7 | S8: 14 | T8: 24 | U8: 5 | V8: 12 | W8: 24 | X8: 5 | Y8: 12 | Z8: =SUM(W8:Y8) -> 41 | AA8: 0 | AB8: 60 | AC8: 0 | AD8: 0 | AE8: 0 | AF8: 1 | AG8: 23 | AH8: 2 | AI8: 1
A9: Probe: did participant fail probe - 1 = yes, 0 = no (to be completed | D9: 120073 | E9: 2 | F9: 2 | G9: 21 | H9: 0 | I9: 3 | J9: 16 | K9: 0 | L9: 3 | M9: 16 | N9: 0 | O9: 3 | P9: =SUM(L9:O9) -> 22 | Q9: 21 | R9: 0 | S9: 3 | T9: 16 | U9: 0 | V9: 3 | W9: 16 | X9: 0 | Y9: 3 | Z9: =SUM(W9:Y9) -> 19 | AA9: 0 | AB9: 60 | AC9: 0 | AD9: 0 | AE9: 0 | AF9: 1 | AG9: 20 | AH9: 1 | AI9: 1
A10: by two independent coders AFTER termination of data collection) | D10: 122535 | E10: 1 | F10: 1 | Q10: 0 | R10: 1 | S10: 0 | T10: 0 | U10: 3 | V10: 0 | W10: 0 | X10: 3 | Y10: 0 | Z10: =SUM(W10:Y10) -> 3 | AA10: 0 | AB10: 40 | AC10: 1 | AD10: 1 | AE10: 1 | AF10: 2 | AG10: 22 | AH10: 1 | AI10: 1
A11: MC = manipulation check (think = 1, not think = 2) | D11: 128377 | E11: 2 | F11: 1 | G11: 23 | H11: 7 | I11: 9 | J11: 21 | K11: 4 | L11: 6 | M11: 21 | N11: 4 | O11: 6 | P11: =SUM(L11:O11) -> 37 | Q11: 23 | R11: 7 | S11: 9 | T11: 21 | U11: 4 | V11: 6 | W11: 21 | X11: 4 | Y11: 6 | Z11: =SUM(W11:Y11) -> 31 | AA11: 0 | AB11: 60 | AC11: 0 | AD11: 0 | AE11: 0 | AF11: 1 | AG11: 23 | AH11: 2 | AI11: 1
A12: Gender: female = 1, male = 2, other = 3, prefer not to say = 4 | D12: 143217 | E12: 2 | F12: 4 | G12: 37 | H12: 3 | I12: 2 | J12: 33 | K12: 1 | L12: 5 | M12: 33 | N12: 1 | O12: 5 | P12: =SUM(L12:O12) -> 44 | Q12: 37 | R12: 3 | S12: 2 | T12: 33 | U12: 1 | V12: 5 | W12: 33 | X12: 1 | Y12: 5 | Z12: =SUM(W12:Y12) -> 39 | AA12: 85 | AB12: 87 | AC12: 0 | AD12: 0 | AE12: 0 | AF12: 1 | AG12: 22 | AH12: 1 | AI12: 1
A13: Compliance: complied with experimental instructions? Yes = 1, No = 2 | D13: 155583 | E13: 2 | F13: 1 | G13: 35 | H13: 3 | I13: 4 | J13: 30 | K13: 3 | L13: 4 | M13: 30 | N13: 3 | O13: 4 | P13: =SUM(L13:O13) -> 41 | Q13: 35 | R13: 3 | S13: 4 | T13: 30 | U13: 3 | V13: 4 | W13: 30 | X13: 3 | Y13: 4 | Z13: =SUM(W13:Y13) -> 37 | AA13: 0 | AB13: 70 | AC13: 0 | AD13: 0 | AE13: 0 | AF13: 1 | AG13: 19 | AH13: 1 | AI13: 1
D14: 160903 | E14: 2 | F14: 4 | G14: 27 | H14: 0 | I14: 8 | J14: 26 | K14: 0 | L14: 7 | M14: 26 | N14: 0 | O14: 7 | P14: =SUM(L14:O14) -> 40 | Q14: 27 | R14: 0 | S14: 8 | T14: 26 | U14: 0 | V14: 7 | W14: 26 | X14: 0 | Y14: 7 | Z14: =SUM(W14:Y14) -> 33 | AA14: 0 | AB14: 90 | AC14: 0 | AD14: 0 | AE14: 0 | AF14: 1 | AG14: 20 | AH14: 1 | AI14: 1
A15: not think = 1 | D15: 170171 | E15: 1 | F15: 4 | Q15: 0 | R15: 2 | S15: 0 | T15: 0 | U15: 4 | V15: 0 | W15: 0 | X15: 2 | Y15: 0 | Z15: =SUM(W15:Y15) -> 2 | AA15: 0 | AB15: 40 | AC15: 1 | AD15: 1 | AE15: 1 | AF15: 1 | AG15: 19 | AH15: 1 | AI15: 1
A16: think =2 | D16: 194097 | E16: 2 | F16: 1 | G16: 6 | H16: 11 | I16: 12 | J16: 9 | K16: 9 | L16: 8 | M16: 6 | N16: 11 | O16: 12 | P16: =SUM(M16:O16) -> 29 | Q16: 6 | R16: 11 | S16: 12 | T16: 9 | U16: 9 | V16: 8 | W16: 6 | X16: 11 | Y16: 12 | Z16: =SUM(W16:Y16) -> 29 | AA16: 0 | AB16: 80 | AC16: 0 | AD16: 0 | AE16: 0 | AF16: 1 | AG16: 20 | AH16: 1 | AI16: 1
D17: 197532 | E17: 2 | F17: 4 | G17: 22 | H17: 0 | I17: 7 | J17: 12 | K17: 0 | L17: 9 | M17: 20 | N17: 0 | O17: 9 | P17: =SUM(M17:O17) -> 29 | Q17: 22 | R17: 0 | S17: 7 | T17: 12 | U17: 0 | V17: 9 | W17: 20 | X17: 0 | Y17: 9 | Z17: =SUM(W17:Y17) -> 29 | AA17: 0 | AB17: 90 | AC17: 0 | AD17: 0 | AE17: 0 | AF17: 1 | AG17: 21 | AH17: 1 | AI17: 1
A18: =ROWS(E6:E126) -> 121 | D18: 197689 | E18: 1 | F18: 3 | Q18: 0 | R18: 2 | S18: 1 | T18: 1 | U18: 7 | V18: 0 | W18: 1 | X18: 7 | Y18: 0 | Z18: =SUM(W18:Y18) -> 8 | AA18: 2 | AB18: 65 | AC18: 1 | AD18: 1 | AE18: 1 | AF18: 1 | AG18: 23 | AH18: 1 | AI18: 2
D19: 199134 | E19: 1 | F19: 3 | Q19: 2 | R19: 2 | S19: 1 | T19: 0 | U19: 3 | V19: 1 | W19: 2 | X19: 2 | Y19: 1 | Z19: =SUM(W19:Y19) -> 5 | AA19: 50 | AB19: 20 | AC19: 1 | AD19: 1 | AE19: 1 | AF19: 2 | AG19: 20 | AH19: 1 | AI19: 1
D20: 203165 | E20: 1 | F20: 2 | Q20: 2 | R20: 3 | S20: 8 | T20: 3 | U20: 4 | V20: 7 | W20: 3 | X20: 4 | Y20: 7 | Z20: =SUM(W20:Y20) -> 14 | AA20: 0 | AB20: 20 | AC20: 1 | AD20: 1 | AE20: 1 | AF20: 2 | AG20: 18 | AH20: 1 | AI20: 1
D21: 205813 | E21: 1 | F21: 1 | Q21: 1 | R21: 1 | S21: 1 | T21: 2 | U21: 3 | V21: 0 | W21: 1 | X21: 1 | Y21: 1 | Z21: =SUM(W21:Y21) -> 3 | AA21: 0 | AB21: 2 | AC21: 1 | AD21: 1 | AE21: 1 | AF21: 2 | AG21: 19 | AH21: 1 | AI21: 1
D22: 215393 | E22: 1 | F22: 3 | Q22: 0 | R22: 12 | S22: 0 | T22: 0 | U22: 8 | V22: 2 | W22: 0 | X22: 8 | Y22: 2 | Z22: =SUM(W22:Y22) -> 10 | AA22: 0 | AB22: 40 | AC22: 1 | AD22: 1 | AE22: 1 | AF22: 2 | AG22: 19 | AH22: 1 | AI22: 1
D23: 222449 | E23: 1 | F23: 1 | Q23: 0 | R23: 2 | S23: 0 | T23: 0 | U23: 3 | V23: 0 | W23: 0 | X23: 3 | Y23: 0 | Z23: =SUM(W23:Y23) -> 3 | AA23: 0 | AB23: 20 | AC23: 1 | AD23: 1 | AE23: 1 | AF23: 2 | AG23: 19 | AH23: 1 | AI23: 1
D24: 224807 | E24: 1 | F24: 2 | Q24: 1 | R24: 7 | S24: 1 | T24: 1 | U24: 5 | V24: 2 | W24: 1 | X24: 7 | Y24: 1 | Z24: =SUM(W24:Y24) -> 9 | AA24: 0 | AB24: 20 | AC24: 1 | AD24: 1 | AE24: 1 | AF24: 2 | AG24: 23 | AH24: 2 | AI24: 1
D25: 243885 | E25: 1 | F25: 3 | Q25: 0 | R25: 1 | S25: 0 | T25: 0 | U25: 1 | V25: 0 | W25: 0 | X25: 1 | Y25: 0 | Z25: =SUM(W25:Y25) -> 1 | AA25: 90 | AB25: 100 | AC25: 1 | AD25: 1 | AE25: 1 | AF25: 2 | AG25: 19 | AH25: 1 | AI25: 1
D26: 250971 | E26: 1 | F26: 2 | Q26: 0 | R26: 2 | S26: 1 | T26: 0 | U26: 2 | V26: 3 | W26: 0 | X26: 2 | Y26: 3 | Z26: =SUM(W26:Y26) -> 5 | AA26: 0 | AB26: 10 | AC26: 1 | AD26: 1 | AE26: 1 | AF26: 2 | AG26: 18 | AH26: 1 | AI26: 1
D27: 256240 | E27: 2 | F27: 3 | G27: 9 | H27: 25 | I27: 21 | J27: 7 | K27: 20 | L27: 23 | M27: 7 | N27: 20 | O27: 23 | P27: =SUM(M27:O27) -> 50 | Q27: 9 | R27: 25 | S27: 21 | T27: 7 | U27: 20 | V27: 23 | W27: 7 | X27: 20 | Y27: 23 | Z27: =SUM(W27:Y27) -> 50 | AA27: 5 | AB27: 90 | AC27: 0 | AD27: 0 | AE27: 0 | AF27: 1 | AG27: 25 | AH27: 2 | AI27: 1
D28: 262983 | E28: 2 | F28: 2 | G28: 5 | H28: 2 | I28: 3 | J28: 3 | K28: 2 | L28: 3 | M28: 3 | N28: 2 | O28: 3 | P28: =SUM(M28:O28) -> 8 | Q28: 5 | R28: 2 | S28: 3 | T28: 3 | U28: 2 | V28: 3 | W28: 3 | X28: 2 | Y28: 3 | Z28: =SUM(W28:Y28) -> 8 | AA28: 0 | AB28: 40 | AC28: 0 | AD28: 0 | AE28: 0 | AF28: 1 | AG28: 19 | AH28: 1 | AI28: 1
D29: 264413 | E29: 2 | F29: 3 | G29: 25 | H29: 3 | I29: 15 | J29: 11 | K29: 5 | L29: 10 | M29: 25 | N29: 3 | O29: 15 | P29: =SUM(M29:O29) -> 43 | Q29: 25 | R29: 3 | S29: 15 | T29: 11 | U29: 5 | V29: 10 | W29: 25 | X29: 3 | Y29: 15 | Z29: =SUM(W29:Y29) -> 43 | AA29: 10 | AB29: 90 | AC29: 0 | AD29: 0 | AE29: 0 | AF29: 1 | AG29: 19 | AH29: 1 | AI29: 1
D30: 265388 | E30: 2 | F30: 3 | G30: 23 | H30: 0 | I30: 10 | J30: 28 | K30: 1 | L30: 8 | M30: 28 | N30: 1 | O30: 8 | P30: =SUM(M30:O30) -> 37 | Q30: 23 | R30: 0 | S30: 10 | T30: 28 | U30: 1 | V30: 8 | W30: 28 | X30: 1 | Y30: 8 | Z30: =SUM(W30:Y30) -> 37 | AA30: 0 | AB30: 100 | AC30: 0 | AD30: 0 | AE30: 0 | AF30: 1 | AG30: 21 | AH30: 1 | AI30: 1
D31: 277194 | E31: 1 | F31: 1 | Q31: 0 | R31: 5 | S31: 0 | T31: 0 | U31: 2 | V31: 0 | W31: 0 | X31: 5 | Y31: 0 | Z31: =SUM(W31:Y31) -> 5 | AA31: 0 | AB31: 20 | AC31: 1 | AD31: 1 | AE31: 1 | AF31: 2 | AG31: 21 | AH31: 1 | AI31: 1
D32: 310918 | E32: 2 | F32: 4 | G32: 25 | H32: 4 | I32: 6 | J32: 21 | K32: 6 | L32: 1 | M32: 25 | N32: 4 | O32: 6 | P32: =SUM(M32:O32) -> 35 | Q32: 25 | R32: 4 | S32: 6 | T32: 21 | U32: 6 | V32: 1 | W32: 25 | X32: 4 | Y32: 6 | Z32: =SUM(W32:Y32) -> 35 | AA32: 0 | AB32: 70 | AC32: 0 | AD32: 0 | AE32: 0 | AF32: 1 | AG32: 22 | AH32: 2 | AI32: 1
D33: 315045 | E33: 1 | F33: 3 | Q33: 2 | R33: 2 | S33: 1 | T33: 1 | U33: 3 | V33: 1 | W33: 1 | X33: 3 | Y33: 1 | Z33: =SUM(W33:Y33) -> 5 | AA33: 10 | AB33: 20 | AC33: 0 | AD33: 0 | AE33: 0 | AF33: 2 | AG33: 21 | AH33: 1 | AI33: 1
D34: 326586 | E34: 1 | F34: 2 | Q34: 0 | R34: 2 | S34: 1 | T34: 0 | U34: 2 | V34: 1 | W34: 0 | X34: 2 | Y34: 1 | Z34: =SUM(W34:Y34) -> 3 | AA34: 0 | AB34: 20 | AC34: 1 | AD34: 1 | AE34: 1 | AF34: 2 | AG34: 21 | AH34: 1 | AI34: 1
D35: 330133 | E35: 2 | F35: 3 | G35: 15 | H35: 7 | I35: 19 | J35: 25 | K35: 3 | L35: 9 | M35: 22 | N35: 5 | O35: 13 | P35: =SUM(M35:O35) -> 40 | Q35: 15 | R35: 7 | S35: 19 | T35: 25 | U35: 3 | V35: 9 | W35: 22 | X35: 5 | Y35: 13 | Z35: =SUM(W35:Y35) -> 40 | AA35: 15 | AB35: 90 | AC35: 0 | AD35: 0 | AE35: 0 | AF35: 1 | AG35: 29 | AH35: 2 | AI35: 1
D36: 341963 | E36: 2 | F36: 4 | G36: 4 | H36: 1 | I36: 14 | J36: 5 | K36: 0 | L36: 12 | M36: 5 | N36: 0 | O36: 12 | P36: =SUM(M36:O36) -> 17 | Q36: 4 | R36: 1 | S36: 14 | T36: 5 | U36: 0 | V36: 12 | W36: 5 | X36: 0 | Y36: 12 | Z36: =SUM(W36:Y36) -> 17 | AA36: 0 | AB36: 80 | AC36: 0 | AD36: 0 | AE36: 0 | AF36: 1 | AG36: 21 | AH36: 1 | AI36: 1
D37: 352082 | E37: 1 | F37: 1 | Q37: 0 | R37: 8 | S37: 8 | T37: 4 | U37: 3 | V37: 4 | W37: 4 | X37: 3 | Y37: 4 | Z37: =SUM(W37:Y37) -> 11 | AA37: 0 | AB37: 20 | AC37: 1 | AD37: 1 | AE37: 1 | AF37: 2 | AG37: 20 | AH37: 1 | AI37: 1
D38: 354902 | E38: 2 | F38: 2 | G38: 0 | H38: 8 | I38: 0 | J38: 0 | K38: 3 | L38: 1 | M38: 0 | N38: 3 | O38: 1 | P38: =SUM(M38:O38) -> 4 | Q38: 0 | R38: 8 | S38: 0 | T38: 0 | U38: 3 | V38: 1 | W38: 0 | X38: 3 | Y38: 1 | Z38: =SUM(W38:Y38) -> 4 | AA38: 0 | AB38: 10 | AC38: 0 | AD38: 0 | AE38: 0 | AF38: 1 | AG38: 20 | AH38: 1 | AI38: 1
D39: 367470 | E39: 1 | F39: 1 | Q39: 0 | R39: 3 | S39: 2 | T39: 0 | U39: 0 | V39: 2 | W39: 0 | X39: 3 | Y39: 2 | Z39: =SUM(W39:Y39) -> 5 | AA39: 0 | AB39: 2 | AC39: 1 | AD39: 1 | AE39: 1 | AF39: 2 | AG39: 22 | AH39: 1 | AI39: 1
D40: 377404 | E40: 1 | F40: 2 | Q40: 0 | R40: 12 | S40: 2 | T40: 1 | U40: 12 | V40: 1 | W40: 0 | X40: 12 | Y40: 2 | Z40: =SUM(W40:Y40) -> 14 | AA40: 0 | AB40: 60 | AC40: 1 | AD40: 1 | AE40: 1 | AF40: 2 | AG40: 23 | AH40: 1 | AI40: 1
...

Sheet summarystats
A1: Correct responses
B2: Concentration | C2: Suppression
A3: High time pressure | B3: =AVERAGEIF('Meilan (before resolving)'!$E$2:$E$11, "Concentration", 'Meilan (before resolving)'!#REF!) -> #REF! | C3: =AVERAGEIF('Meilan (before resolving)'!$E$2:$E$11, "Suppression", 'Meilan (before resolving)'!#REF!) -> #REF!
A4: Low time pressure | B4: =AVERAGEIF('Meilan (before resolving)'!$E$2:$E$11, "Concentration", 'Meilan (before resolving)'!#REF!) -> #REF! | C4: =AVERAGEIF('Meilan (before resolving)'!$E$2:$E$11, "Suppression", 'Meilan (before resolving)'!#REF!) -> #REF!
A6: RT responses
B7: Concentration | C7: Suppression
A8: High time pressure | B8: =AVERAGEIF('Meilan (before resolving)'!$E$2:$E$11, "Concentration", 'Meilan (before resolving)'!#REF!) -> #REF! | C8: =AVERAGEIF('Meilan (before resolving)'!$E$2:$E$11, "Suppression", 'Meilan (before resolving)'!#REF!) -> #REF!
A9: Low time pressure | B9: =AVERAGEIF('Meilan (before resolving)'!$E$2:$E$11, "Concentration", 'Meilan (before resolving)'!#REF!) -> #REF! | C9: =AVERAGEIF('Meilan (before resolving)'!$E$2:$E$11, "Suppression", 'Meilan (before resolving)'!#REF!) -> #REF!
