Workbook

Sheet testdata
A1: Participant ID | B1: Researcher | C1: Table.citation | D1: Lab | E1: Country | F1: Condition | G1: Target word | H1: Time pressure order | I1: target.low1.coder1 | J1: target.low2.coder1 | K1: target.high1.coder1 | L1: target.high2.coder1 | M1: nontarget.low1.coder1 | N1: nontarget.low2.coder1 | O1: nontarget.high1.coder1 | P1: nontarget.high2.coder1 | Q1: target.low1.coder2 | R1: target.low2.coder2 | S1: target.high1.coder2 | T1: target.high2.coder2 | U1: nontarget.low1.coder2 | V1: nontarget.low2.coder2 | W1: nontarget.high1.coder2 | X1: nontarget.high2.coder2 | Y1: target.low1.final | Z1: target.low2.final | AA1: target.high1.final | AB1: target.high2.final | AC1: nontarget.low1.final | AD1: nontarget.low2.final | AE1: nontarget.high1.final | AF1: nontarget.high2.final | AG1: mean.target.low | AH1: mean.target.high | AI1: mean.nontarget.low | AJ1: mean.nontarget.high | AK1: probe.coder1 | AL1: probe.coder2 | AM1: probe.final | AN1: MC | AO1: age | AP1: gender | AQ1: Compliance
A2: 121 | B2: Richard Lopez | C2: Lopez et al. | D2: Worcester Polytechnic Institute | E2: USA | F2: 1 | G2: 4 | H2: 1 | I2: 0 | J2: 0 | K2: 0 | L2: 0 | M2: 0 | N2: 0 | O2: 0 | P2: 1 | Q2: 0 | R2: 0 | S2: 0 | T2: 0 | U2: 0 | V2: 0 | W2: 0 | X2: 1 | Y2: 0 | Z2: 0 | AA2: 0 | AB2: 0 | AC2: 0 | AD2: 0 | AE2: 0 | AF2: 1 | AG2: =AVERAGE(Y2:Z2) -> 0 | AH2: =AVERAGE(AA2:AB2) -> 0 | AI2: =AVERAGE(AC2:AD2) -> 0 | AJ2: =AVERAGE(AE2:AF2) -> 0.5 | AK2: 0 | AL2: 0 | AM2: 0 | AN2: 2 | AO2: 21 | AP2: 1 | AQ2: 1
A3: 122 | B3: Richard Lopez | C3: Lopez et al. | D3: Worcester Polytechnic Institute | E3: USA | F3: 1 | G3: 3 | H3: 2 | I3: 0 | J3: 0 | K3: 0 | L3: 0 | M3: 0 | N3: 0 | O3: 1 | P3: 0 | Q3: 0 | R3: 0 | S3: 0 | T3: 0 | U3: 0 | V3: 0 | W3: 1 | X3: 0 | Y3: 0 | Z3: 0 | AA3: 0 | AB3: 0 | AC3: 0 | AD3: 0 | AE3: 1 | AF3: 0 | AG3: =AVERAGE(Y3:Z3) -> 0 | AH3: =AVERAGE(AA3:AB3) -> 0 | AI3: =AVERAGE(AC3:AD3) -> 0 | AJ3: =AVERAGE(AE3:AF3) -> 0.5 | AK3: 0 | AL3: 0 | AM3: 0 | AN3: 2 | AO3: 20 | AP3: 2 | AQ3: 1
A4: 123 | B4: Richard Lopez | C4: Lopez et al. | D4: Worcester Polytechnic Institute | E4: USA | F4: 1 | G4: 2 | H4: 1 | I4: 1 | J4: 1 | K4: 1 | L4: 1 | M4: 0 | N4: 0 | O4: 0 | P4: 0 | Q4: 1 | R4: 1 | S4: 1 | T4: 1 | U4: 0 | V4: 0 | W4: 0 | X4: 0 | Y4: 1 | Z4: 1 | AA4: 1 | AB4: 1 | AC4: 0 | AD4: 0 | AE4: 0 | AF4: 0 | AG4: =AVERAGE(Y4:Z4) -> 1 | AH4: =AVERAGE(AA4:AB4) -> 1 | AI4: =AVERAGE(AC4:AD4) -> 0 | AJ4: =AVERAGE(AE4:AF4) -> 0 | AK4: 0 | AL4: 0 | AM4: 0 | AN4: 2 | AO4: 17 | AP4: 1 | AQ4: 1
A5: 124 | B5: Richard Lopez | C5: Lopez et al. | D5: Worcester Polytechnic Institute | E5: USA | F5: 2 | G5: 2 | H5: 2 | I5: 1 | J5: 0 | K5: 0 | L5: 0 | M5: 1 | N5: 0 | O5: 0 | P5: 0 | Q5: 1 | R5: 0 | S5: 0 | T5: 0 | U5: 1 | V5: 0 | W5: 0 | X5: 0 | Y5: 1 | Z5: 0 | AA5: 0 | AB5: 0 | AC5: 1 | AD5: 0 | AE5: 0 | AF5: 0 | AG5: =AVERAGE(Y5:Z5) -> 0.5 | AH5: =AVERAGE(AA5:AB5) -> 0 | AI5: =AVERAGE(AC5:AD5) -> 0.5 | AJ5: =AVERAGE(AE5:AF5) -> 0 | AK5: 0 | AL5: 0 | AM5: 0 | AN5: 1 | AO5: 17 | AP5: 1 | AQ5: 1
A6: 125 | B6: Richard Lopez | C6: Lopez et al. | D6: Worcester Polytechnic Institute | E6: USA | F6: 2 | G6: 4 | H6: 1 | I6: 0 | J6: 0 | K6: 1 | L6: 0 | M6: 0 | N6: 0 | O6: 0 | P6: 0 | Q6: 0 | R6: 0 | S6: 1 | T6: 0 | U6: 0 | V6: 0 | W6: 0 | X6: 0 | Y6: 0 | Z6: 0 | AA6: 1 | AB6: 0 | AC6: 0 | AD6: 0 | AE6: 0 | AF6: 0 | AG6: =AVERAGE(Y6:Z6) -> 0 | AH6: =AVERAGE(AA6:AB6) -> 0.5 | AI6: =AVERAGE(AC6:AD6) -> 0 | AJ6: =AVERAGE(AE6:AF6) -> 0 | AK6: 1 | AL6: 1 | AM6: 1 | AN6: 2 | AO6: 20 | AP6: 2 | AQ6: 1
A7: 126 | B7: Richard Lopez | C7: Lopez et al. | D7: Worcester Polytechnic Institute | E7: USA | F7: 2 | G7: 1 | H7: 2 | I7: 0 | J7: 0 | K7: 0 | L7: 0 | M7: 0 | N7: 0 | O7: 0 | P7: 1 | Q7: 0 | R7: 0 | S7: 0 | T7: 0 | U7: 0 | V7: 0 | W7: 0 | X7: 1 | Y7: 0 | Z7: 0 | AA7: 0 | AB7: 0 | AC7: 0 | AD7: 0 | AE7: 0 | AF7: 1 | AG7: =AVERAGE(Y7:Z7) -> 0 | AH7: =AVERAGE(AA7:AB7) -> 0 | AI7: =AVERAGE(AC7:AD7) -> 0 | AJ7: =AVERAGE(AE7:AF7) -> 0.5 | AK7: 0 | AL7: 0 | AM7: 0 | AN7: 1 | AO7: 23 | AP7: 2 | AQ7: 1
A8: 127 | B8: Richard Lopez | C8: Lopez et al. | D8: Worcester Polytechnic Institute | E8: USA | F8: 2 | G8: 2 | H8: 2 | I8: 0 | J8: 0 | K8: 1 | L8: 0 | M8: 0 | N8: 0 | O8: 0 | P8: 0 | Q8: 0 | R8: 0 | S8: 1 | T8: 0 | U8: 0 | V8: 0 | W8: 0 | X8: 0 | Y8: 0 | Z8: 0 | AA8: 1 | AB8: 0 | AC8: 0 | AD8: 0 | AE8: 0 | AF8: 0 | AG8: =AVERAGE(Y8:Z8) -> 0 | AH8: =AVERAGE(AA8:AB8) -> 0.5 | AI8: =AVERAGE(AC8:AD8) -> 0 | AJ8: =AVERAGE(AE8:AF8) -> 0 | AK8: 0 | AL8: 0 | AM8: 0 | AN8: 1 | AO8: 21 | AP8: 1 | AQ8: 1
A9: 128 | B9: Richard Lopez | C9: Lopez et al. | D9: Worcester Polytechnic Institute | E9: USA | F9: 1 | G9: 3 | H9: 2 | I9: 0 | J9: 0 | K9: 0 | L9: 0 | M9: 0 | N9: 0 | O9: 0 | P9: 0 | Q9: 0 | R9: 0 | S9: 0 | T9: 0 | U9: 0 | V9: 0 | W9: 0 | X9: 0 | Y9: 0 | Z9: 0 | AA9: 0 | AB9: 0 | AC9: 0 | AD9: 0 | AE9: 0 | AF9: 0 | AG9: =AVERAGE(Y9:Z9) -> 0 | AH9: =AVERAGE(AA9:AB9) -> 0 | AI9: =AVERAGE(AC9:AD9) -> 0 | AJ9: =AVERAGE(AE9:AF9) -> 0 | AK9: 0 | AL9: 0 | AM9: 0 | AN9: 2 | AO9: 20 | AP9: 1 | AQ9: 1
A10: 129 | B10: Richard Lopez | C10: Lopez et al. | D10: Worcester Polytechnic Institute | E10: USA | F10: 1 | G10: 4 | H10: 2 | I10: 0 | J10: 0 | K10: 0 | L10: 0 | M10: 0 | N10: 0 | O10: 0 | P10: 0 | Q10: 0 | R10: 0 | S10: 0 | T10: 0 | U10: 0 | V10: 0 | W10: 0 | X10: 0 | Y10: 0 | Z10: 0 | AA10: 0 | AB10: 0 | AC10: 0 | AD10: 0 | AE10: 0 | AF10: 0 | AG10: =AVERAGE(Y10:Z10) -> 0 | AH10: =AVERAGE(AA10:AB10) -> 0 | AI10: =AVERAGE(AC10:AD10) -> 0 | AJ10: =AVERAGE(AE10:AF10) -> 0 | AK10: 0 | AL10: 0 | AM10: 0 | AN10: 2 | AO10: 21 | AP10: 2 | AQ10: 1
A11: 130 | B11: Richard Lopez | C11: Lopez et al. | D11: Worcester Polytechnic Institute | E11: USA | F11: 2 | G11: 4 | H11: 1 | I11: 0 | J11: 0 | K11: 0 | L11: 0 | M11: 0 | N11: 0 | O11: 0 | P11: 1 | Q11: 0 | R11: 0 | S11: 0 | T11: 0 | U11: 0 | V11: 0 | W11: 0 | X11: 1 | Y11: 0 | Z11: 0 | AA11: 0 | AB11: 0 | AC11: 0 | AD11: 0 | AE11: 0 | AF11: 1 | AG11: =AVERAGE(Y11:Z11) -> 0 | AH11: =AVERAGE(AA11:AB11) -> 0 | AI11: =AVERAGE(AC11:AD11) -> 0 | AJ11: =AVERAGE(AE11:AF11) -> 0.5 | AK11: 0 | AL11: 0 | AM11: 0 | AN11: 1 | AO11: 20 | AP11: 2 | AQ11: 1
A12: 131 | B12: Richard Lopez | C12: Lopez et al. | D12: Worcester Polytechnic Institute | E12: USA | F12: 2 | G12: 2 | H12: 2 | I12: 1 | J12: 0 | K12: 0 | L12: 1 | M12: 1 | N12: 0 | O12: 0 | P12: 0 | Q12: 1 | R12: 0 | S12: 0 | T12: 1 | U12: 1 | V12: 0 | W12: 0 | X12: 0 | Y12: 1 | Z12: 0 | AA12: 0 | AB12: 1 | AC12: 1 | AD12: 0 | AE12: 0 | AF12: 0 | AG12: =AVERAGE(Y12:Z12) -> 0.5 | AH12: =AVERAGE(AA12:AB12) -> 0.5 | AI12: =AVERAGE(AC12:AD12) -> 0.5 | AJ12: =AVERAGE(AE12:AF12) -> 0 | AK12: 0 | AL12: 0 | AM12: 0 | AN12: 1 | AO12: 19 | AP12: 1 | AQ12: 1
A13: 132 | B13: Richard Lopez | C13: Lopez et al. | D13: Worcester Polytechnic Institute | E13: USA | F13: 2 | G13: 4 | H13: 2 | I13: 1 | J13: 0 | K13: 1 | L13: 0 | M13: 0 | N13: 0 | O13: 0 | P13: 1 | Q13: 1 | R13: 0 | S13: 1 | T13: 0 | U13: 0 | V13: 0 | W13: 0 | X13: 1 | Y13: 1 | Z13: 0 | AA13: 1 | AB13: 0 | AC13: 0 | AD13: 0 | AE13: 0 | AF13: 1 | AG13: =AVERAGE(Y13:Z13) -> 0.5 | AH13: =AVERAGE(AA13:AB13) -> 0.5 | AI13: =AVERAGE(AC13:AD13) -> 0 | AJ13: =AVERAGE(AE13:AF13) -> 0.5 | AK13: 0 | AL13: 0 | AM13: 0 | AN13: 1 | AO13: 17 | AP13: 1 | AQ13: 1
... A27: 146 | B27: Richard Lopez | C27: Lopez et al. | D27: Worcester Polytechnic Institute | E27: USA | F27: 1 | G27: 1 | H27: 2 | I27: 1 | J27: 0 | K27: 1 | L27: 0 | M27: 0 | N27: 0 | O27: 0 | P27: 1 | Q27: 1 | R27: 0 | S27: 1 | T27: 0 | U27: 0 | V27: 0 | W27: 0 | X27: 1 | Y27: 1 | Z27: 0 | AA27: 1 | AB27: 0 | AC27: 0 | AD27: 0 | AE27: 0 | AF27: 1 | AG27: =AVERAGE(Y27:Z27) -> 0.5 | AH27: =AVERAGE(AA27:AB27) -> 0.5 | AI27: =AVERAGE(AC27:AD27) -> 0 | AJ27: =AVERAGE(AE27:AF27) -> 0.5 | AK27: 0 | AL27: 0 | AM27: 0 | AN27: 2 | AO27: 18 | AP27: 3 | AQ27: 1
A28: 147 | B28: Richard Lopez | C28: Lopez et al. | D28: Worcester Polytechnic Institute | E28: USA | F28: 2 | G28: 2 | H28: 1 | I28: NA | J28: NA | K28: NA | L28: NA | M28: NA | N28: NA | O28: NA | P28: NA | Q28: NA | R28: NA | S28: NA | T28: NA | U28: NA | V28: NA | W28: NA | X28: NA | Y28: NA | Z28: NA | AA28: NA | AB28: NA | AC28: NA | AD28: NA | AE28: NA | AF28: NA | AG28: NA | AH28: NA | AI28: NA | AJ28: NA | AK28: 0 | AL28: 0 | AM28: 0 | AN28: 1 | AO28: 19 | AP28: 1 | AQ28: 1
A29: 148 | B29: Richard Lopez | C29: Lopez et al. | D29: Worcester Polytechnic Institute | E29: USA | F29: 1 | G29: 1 | H29: 2 | I29: 0 | J29: 0 | K29: 0 | L29: 0 | M29: 0 | N29: 0 | O29: 0 | P29: 1 | Q29: 0 | R29: 0 | S29: 0 | T29: 0 | U29: 0 | V29: 0 | W29: 0 | X29: 1 | Y29: 0 | Z29: 0 | AA29: 0 | AB29: 0 | AC29: 0 | AD29: 0 | AE29: 0 | AF29: 1 | AG29: =AVERAGE(Y29:Z29) -> 0 | AH29: =AVERAGE(AA29:AB29) -> 0 | AI29: =AVERAGE(AC29:AD29) -> 0 | AJ29: =AVERAGE(AE29:AF29) -> 0.5 | AK29: 0 | AL29: 0 | AM29: 0 | AN29: 2 | AO29: 19 | AP29: 2 | AQ29: 1
A30: 149 | B30: Richard Lopez | C30: Lopez et al. | D30: Worcester Polytechnic Institute | E30: USA | F30: 2 | G30: 3 | H30: 1 | I30: NA | J30: NA | K30: NA | L30: NA | M30: NA | N30: NA | O30: NA | P30: NA | Q30: NA | R30: NA | S30: NA | T30: NA | U30: NA | V30: NA | W30: NA | X30: NA | Y30: NA | Z30: NA | AA30: NA | AB30: NA | AC30: NA | AD30: NA | AE30: NA | AF30: NA | AG30: NA | AH30: NA | AI30: NA | AJ30: NA | AK30: 0 | AL30: 0 | AM30: 0 | AN30: 1 | AO30: 18 | AP30: 1 | AQ30: 1
A31: 150 | B31: Richard Lopez | C31: Lopez et al. | D31: Worcester Polytechnic Institute | E31: USA | F31: 1 | G31: 4 | H31: 2 | I31: 0 | J31: 0 | K31: 0 | L31: 0 | M31: 0 | N31: 1 | O31: 0 | P31: 0 | Q31: 0 | R31: 0 | S31: 0 | T31: 0 | U31: 0 | V31: 1 | W31: 0 | X31: 0 | Y31: 0 | Z31: 0 | AA31: 0 | AB31: 0 | AC31: 0 | AD31: 1 | AE31: 0 | AF31: 0 | AG31: =AVERAGE(Y31:Z31) -> 0 | AH31: =AVERAGE(AA31:AB31) -> 0 | AI31: =AVERAGE(AC31:AD31) -> 0.5 | AJ31: =AVERAGE(AE31:AF31) -> 0 | AK31: 0 | AL31: 0 | AM31: 0 | AN31: 2 | AO31: 20 | AP31: 1 | AQ31: 1
A32: 151 | B32: Richard Lopez | C32: Lopez et al. | D32: Worcester Polytechnic Institute | E32: USA | F32: 2 | G32: 1 | H32: 1 | I32: 0 | J32: 0 | K32: 0 | L32: 0 | M32: 0 | N32: 0 | O32: 0 | P32: 0 | Q32: 0 | R32: 0 | S32: 0 | T32: 0 | U32: 0 | V32: 0 | W32: 0 | X32: 0 | Y32: 0 | Z32: 0 | AA32: 0 | AB32: 0 | AC32: 0 | AD32: 0 | AE32: 0 | AF32: 0 | AG32: =AVERAGE(Y32:Z32) -> 0 | AH32: =AVERAGE(AA32:AB32) -> 0 | AI32: =AVERAGE(AC32:AD32) -> 0 | AJ32: =AVERAGE(AE32:AF32) -> 0 | AK32: 0 | AL32: 0 | AM32: 0 | AN32: 1 | AO32: 19 | AP32: 1 | AQ32: 1
A33: 152 | B33: Richard Lopez | C33: Lopez et al. | D33: Worcester Polytechnic Institute | E33: USA | F33: 2 | G33: 4 | H33: 1 | I33: 0 | J33: 1 | K33: 0 | L33: 0 | M33: 0 | N33: 0 | O33: 0 | P33: 0 | Q33: 0 | R33: 1 | S33: 0 | T33: 0 | U33: 0 | V33: 0 | W33: 0 | X33: 0 | Y33: 0 | Z33: 1 | AA33: 0 | AB33: 0 | AC33: 0 | AD33: 0 | AE33: 0 | AF33: 0 | AG33: =AVERAGE(Y33:Z33) -> 0.5 | AH33: =AVERAGE(AA33:AB33) -> 0 | AI33: =AVERAGE(AC33:AD33) -> 0 | AJ33: =AVERAGE(AE33:AF33) -> 0 | AK33: 1 | AL33: 1 | AM33: 1 | AN33: 2 | AO33: 18 | AP33: 1 | AQ33: 1
A34: 153 | B34: Richard Lopez | C34: Lopez et al. | D34: Worcester Polytechnic Institute | E34: USA | F34: 1 | G34: 1 | H34: 1 | I34: 0 | J34: 0 | K34: 0 | L34: 1 | M34: 1 | N34: 0 | O34: 1 | P34: 1 | Q34: 0 | R34: 0 | S34: 0 | T34: 1 | U34: 1 | V34: 0 | W34: 1 | X34: 1 | Y34: 0 | Z34: 0 | AA34: 0 | AB34: 1 | AC34: 1 | AD34: 0 | AE34: 1 | AF34: 1 | AG34: =AVERAGE(Y34:Z34) -> 0 | AH34: =AVERAGE(AA34:AB34) -> 0.5 | AI34: =AVERAGE(AC34:AD34) -> 0.5 | AJ34: =AVERAGE(AE34:AF34) -> 1 | AK34: 0 | AL34: 0 | AM34: 0 | AN34: 2 | AO34: 18 | AP34: 2 | AQ34: 1
A35: 154 | B35: Richard Lopez | C35: Lopez et al. | D35: Worcester Polytechnic Institute | E35: USA | F35: 1 | G35: 3 | H35: 1 | I35: 0 | J35: 0 | K35: 0 | L35: 0 | M35: 0 | N35: 1 | O35: 0 | P35: 0 | Q35: 0 | R35: 0 | S35: 0 | T35: 0 | U35: 0 | V35: 1 | W35: 0 | X35: 0 | Y35: 0 | Z35: 0 | AA35: 0 | AB35: 0 | AC35: 0 | AD35: 1 | AE35: 0 | AF35: 0 | AG35: =AVERAGE(Y35:Z35) -> 0 | AH35: =AVERAGE(AA35:AB35) -> 0 | AI35: =AVERAGE(AC35:AD35) -> 0.5 | AJ35: =AVERAGE(AE35:AF35) -> 0 | AK35: 0 | AL35: 0 | AM35: 0 | AN35: 2 | AO35: 20 | AP35: 1 | AQ35: 1
A36: 155 | B36: Richard Lopez | C36: Lopez et al. | D36: Worcester Polytechnic Institute | E36: USA | F36: 1 | G36: 1 | H36: 2 | I36: 0 | J36: 0 | K36: 0 | L36: 0 | M36: 0 | N36: 0 | O36: 0 | P36: 1 | Q36: 0 | R36: 0 | S36: 0 | T36: 0 | U36: 0 | V36: 0 | W36: 0 | X36: 1 | Y36: 0 | Z36: 0 | AA36: 0 | AB36: 0 | AC36: 0 | AD36: 0 | AE36: 0 | AF36: 1 | AG36: =AVERAGE(Y36:Z36) -> 0 | AH36: =AVERAGE(AA36:AB36) -> 0 | AI36: =AVERAGE(AC36:AD36) -> 0 | AJ36: =AVERAGE(AE36:AF36) -> 0.5 | AK36: 0 | AL36: 0 | AM36: 0 | AN36: 2 | AO36: 19 | AP36: 2 | AQ36: 1
A37: 156 | B37: Richard Lopez | C37: Lopez et al. | D37: Worcester Polytechnic Institute | E37: USA | F37: 1 | G37: 3 | H37: 2 | I37: 0 | J37: 0 | K37: 0 | L37: 0 | M37: 0 | N37: 0 | O37: 0 | P37: 0 | Q37: 0 | R37: 0 | S37: 0 | T37: 0 | U37: 0 | V37: 0 | W37: 0 | X37: 0 | Y37: 0 | Z37: 0 | AA37: 0 | AB37: 0 | AC37: 0 | AD37: 0 | AE37: 0 | AF37: 0 | AG37: =AVERAGE(Y37:Z37) -> 0 | AH37: =AVERAGE(AA37:AB37) -> 0 | AI37: =AVERAGE(AC37:AD37) -> 0 | AJ37: =AVERAGE(AE37:AF37) -> 0 | AK37: 0 | AL37: 0 | AM37: 0 | AN37: 2 | AO37: 19 | AP37: 1 | AQ37: 1
A38: 157 | B38: Richard Lopez | C38: Lopez et al. | D38: Worcester Polytechnic Institute | E38: USA | F38: 1 | G38: 2 | H38: 1 | I38: 0 | J38: 0 | K38: 0 | L38: 0 | M38: 0 | N38: 0 | O38: 0 | P38: 0 | Q38: 0 | R38: 0 | S38: 0 | T38: 0 | U38: 0 | V38: 0 | W38: 0 | X38: 0 | Y38: 0 | Z38: 0 | AA38: 0 | AB38: 0 | AC38: 0 | AD38: 0 | AE38: 0 | AF38: 0 | AG38: =AVERAGE(Y38:Z38) -> 0 | AH38: =AVERAGE(AA38:AB38) -> 0 | AI38: =AVERAGE(AC38:AD38) -> 0 | AJ38: =AVERAGE(AE38:AF38) -> 0 | AK38: 0 | AL38: 0 | AM38: 0 | AN38: 2 | AO38: 18 | AP38: 1 | AQ38: 1
A39: 158 | B39: Richard Lopez | C39: Lopez et al. | D39: Worcester Polytechnic Institute | E39: USA | F39: 2 | G39: 1 | H39: 1 | I39: 1 | J39: 0 | K39: 0 | L39: 0 | M39: 1 | N39: 1 | O39: 0 | P39: 0 | Q39: 1 | R39: 0 | S39: 0 | T39: 0 | U39: 1 | V39: 1 | W39: 0 | X39: 0 | Y39: 1 | Z39: 0 | AA39: 0 | AB39: 0 | AC39: 1 | AD39: 1 | AE39: 0 | AF39: 0 | AG39: =AVERAGE(Y39:Z39) -> 0.5 | AH39: =AVERAGE(AA39:AB39) -> 0 | AI39: =AVERAGE(AC39:AD39) -> 1 | AJ39: =AVERAGE(AE39:AF39) -> 0 | AK39: 0 | AL39: 0 | AM39: 0 | AN39: 1 | AO39: 18 | AP39: 1 | AQ39: 1
A40: 159 | B40: Richard Lopez | C40: Lopez et al. | D40: Worcester Polytechnic Institute | E40: USA | F40: 2 | G40: 2 | H40: 2 | I40: 1 | J40: 0 | K40: 1 | L40: 0 | M40: 1 | N40: 0 | O40: 0 | P40: 0 | Q40: 1 | R40: 0 | S40: 1 | T40: 0 | U40: 1 | V40: 1 | W40: 0 | X40: 0 | Y40: 1 | Z40: 0 | AA40: 1 | AB40: 0 | AC40: 1 | AD40: 0 | AE40: 0 | AF40: 0 | AG40: =AVERAGE(Y40:Z40) -> 0.5 | AH40: =AVERAGE(AA40:AB40) -> 0.5 | AI40: =AVERAGE(AC40:AD40) -> 0.5 | AJ40: =AVERAGE(AE40:AF40) -> 0 | AK40: 0 | AL40: 0 | AM40: 0 | AN40: 1 | AO40: 19 | AP40: 1 | AQ40: 1
A41: 160 | B41: Richard Lopez | C41: Lopez et al. | D41: Worcester Polytechnic Institute | E41: USA | F41: 1 | G41: 4 | H41: 2 | I41: 0 | J41: 0 | K41: 0 | L41: 0 | M41: 0 | N41: 1 | O41: 0 | P41: 1 | Q41: 0 | R41: 0 | S41: 0 | T41: 0 | U41: 0 | V41: 1 | W41: 0 | X41: 1 | Y41: 0 | Z41: 0 | AA41: 0 | AB41: 0 | AC41: 0 | AD41: 1 | AE41: 0 | AF41: 1 | AG41: =AVERAGE(Y41:Z41) -> 0 | AH41: =AVERAGE(AA41:AB41) -> 0 | AI41: =AVERAGE(AC41:AD41) -> 0.5 | AJ41: =AVERAGE(AE41:AF41) -> 0.5 | AK41: 0 | AL41: 0 | AM41: 0 | AN41: 2 | AO41: 20 | AP41: 2 | AQ41: 1
A42: 161 | B42: Richard Lopez | C42: Lopez et al. | D42: Worcester Polytechnic Institute | E42: USA | F42: 1 | G42: 3 | H42: 2 | I42: 0 | J42: 0 | K42: 0 | L42: 0 | M42: 0 | N42: 0 | O42: 0 | P42: 1 | Q42: 0 | R42: 0 | S42: 0 | T42: 0 | U42: 0 | V42: 0 | W42: 0 | X42: 1 | Y42: 0 | Z42: 0 | AA42: 0 | AB42: 0 | AC42: 0 | AD42: 0 | AE42: 0 | AF42: 1 | AG42: =AVERAGE(Y42:Z42) -> 0 | AH42: =AVERAGE(AA42:AB42) -> 0 | AI42: =AVERAGE(AC42:AD42) -> 0 | AJ42: =AVERAGE(AE42:AF42) -> 0.5 | AK42: 0 | AL42: 0 | AM42: 0 | AN42: 2 | AO42: 22 | AP42: 1 | AQ42: 1
... A60: 179 | B60: Richard Lopez | C60: Lopez et al. | D60: Worcester Polytechnic Institute | E60: USA | F60: 2 | G60: 1 | H60: 1 | I60: 0 | J60: 0 | K60: 0 | L60: 0 | M60: 1 | N60: 0 | O60: 0 | P60: 0 | Q60: 0 | R60: 0 | S60: 0 | T60: 0 | U60: 1 | V60: 0 | W60: 0 | X60: 0 | Y60: 0 | Z60: 0 | AA60: 0 | AB60: 0 | AC60: 1 | AD60: 0 | AE60: 0 | AF60: 0 | AG60: =AVERAGE(Y60:Z60) -> 0 | AH60: =AVERAGE(AA60:AB60) -> 0 | AI60: =AVERAGE(AC60:AD60) -> 0.5 | AJ60: =AVERAGE(AE60:AF60) -> 0 | AK60: 0 | AL60: 0 | AM60: 0 | AN60: 1 | AO60: 21 | AP60: 1 | AQ60: 1
A61: 180 | B61: Richard Lopez | C61: Lopez et al. | D61: Worcester Polytechnic Institute | E61: USA | F61: 2 | G61: 3 | H61: 2 | I61: NA | J61: NA | K61: NA | L61: NA | M61: NA | N61: NA | O61: NA | P61: NA | Q61: NA | R61: NA | S61: NA | T61: NA | U61: NA | V61: NA | W61: NA | X61: NA | Y61: NA | Z61: NA | AA61: NA | AB61: NA | AC61: NA | AD61: NA | AE61: NA | AF61: NA | AG61: =AVERAGE(Y61:Z61) -> #DIV/0! | AH61: =AVERAGE(AA61:AB61) -> #DIV/0! | AI61: =AVERAGE(AC61:AD61) -> #DIV/0! | AJ61: =AVERAGE(AE61:AF61) -> #DIV/0! | AK61: 0 | AL61: 0 | AM61: 0 | AN61: 1 | AO61: 19 | AP61: 2 | AQ61: 1
A62: 181 | B62: Richard Lopez | C62: Lopez et al. | D62: Worcester Polytechnic Institute | E62: USA | F62: 2 | G62: 2 | H62: 1 | I62: 1 | J62: 0 | K62: 1 | L62: 0 | M62: 0 | N62: 1 | O62: 0 | P62: 0 | Q62: 1 | R62: 0 | S62: 1 | T62: 0 | U62: 0 | V62: 1 | W62: 0 | X62: 0 | Y62: 1 | Z62: 0 | AA62: 1 | AB62: 0 | AC62: 0 | AD62: 1 | AE62: 0 | AF62: 0 | AG62: =AVERAGE(Y62:Z62) -> 0.5 | AH62: =AVERAGE(AA62:AB62) -> 0.5 | AI62: =AVERAGE(AC62:AD62) -> 0.5 | AJ62: =AVERAGE(AE62:AF62) -> 0 | AK62: 0 | AL62: 0 | AM62: 0 | AN62: 1 | AO62: 23 | AP62: 1 | AQ62: 1
A63: 182 | B63: Richard Lopez | C63: Lopez et al. | D63: Worcester Polytechnic Institute | E63: USA | F63: 1 | G63: 2 | H63: 2 | I63: 0 | J63: 0 | K63: 0 | L63: 0 | M63: 1 | N63: 0 | O63: 1 | P63: 0 | Q63: 0 | R63: 0 | S63: 0 | T63: 0 | U63: 1 | V63: 0 | W63: 1 | X63: 0 | Y63: 0 | Z63: 0 | AA63: 0 | AB63: 0 | AC63: 1 | AD63: 0 | AE63: 1 | AF63: 0 | AG63: =AVERAGE(Y63:Z63) -> 0 | AH63: =AVERAGE(AA63:AB63) -> 0 | AI63: =AVERAGE(AC63:AD63) -> 0.5 | AJ63: =AVERAGE(AE63:AF63) -> 0.5 | AK63: 0 | AL63: 0 | AM63: 0 | AN63: 2 | AO63: 21 | AP63: 1 | AQ63: 1
A64: 183 | B64: Richard Lopez | C64: Lopez et al. | D64: Worcester Polytechnic Institute | E64: USA | F64: 1 | G64: 2 | H64: 2 | I64: 1 | J64: 0 | K64: 0 | L64: 0 | M64: 0 | N64: 0 | O64: 0 | P64: 0 | Q64: 1 | R64: 0 | S64: 0 | T64: 0 | U64: 0 | V64: 0 | W64: 0 | X64: 0 | Y64: 1 | Z64: 0 | AA64: 0 | AB64: 0 | AC64: 0 | AD64: 0 | AE64: 0 | AF64: 0 | AG64: =AVERAGE(Y64:Z64) -> 0.5 | AH64: =AVERAGE(AA64:AB64) -> 0 | AI64: =AVERAGE(AC64:AD64) -> 0 | AJ64: =AVERAGE(AE64:AF64) -> 0 | AK64: 0 | AL64: 0 | AM64: 0 | AN64: 2 | AO64: 20 | AP64: 1 | AQ64: 1
A65: 184 | B65: Richard Lopez | C65: Lopez et al. | D65: Worcester Polytechnic Institute | E65: USA | F65: 1 | G65: 4 | H65: 1 | I65: 0 | J65: 0 | K65: 1 | L65: 0 | M65: 0 | N65: 1 | O65: 0 | P65: 0 | Q65: 0 | R65: 0 | S65: 1 | T65: 0 | U65: 0 | V65: 1 | W65: 0 | X65: 0 | Y65: 0 | Z65: 0 | AA65: 1 | AB65: 0 | AC65: 0 | AD65: 1 | AE65: 0 | AF65: 0 | AG65: =AVERAGE(Y65:Z65) -> 0 | AH65: =AVERAGE(AA65:AB65) -> 0.5 | AI65: =AVERAGE(AC65:AD65) -> 0.5 | AJ65: =AVERAGE(AE65:AF65) -> 0 | AK65: 0 | AL65: 0 | AM65: 0 | AN65: 2 | AO65: 19 | AP65: 2 | AQ65: 1
A66: 185 | B66: Richard Lopez | C66: Lopez et al. | D66: Worcester Polytechnic Institute | E66: USA | F66: 2 | G66: 4 | H66: 1 | I66: 1 | J66: 1 | K66: 0 | L66: 0 | M66: 0 | N66: 0 | O66: 0 | P66: 0 | Q66: 1 | R66: 1 | S66: 0 | T66: 0 | U66: 0 | V66: 0 | W66: 0 | X66: 0 | Y66: 1 | Z66: 1 | AA66: 0 | AB66: 0 | AC66: 0 | AD66: 0 | AE66: 0 | AF66: 0 | AG66: =AVERAGE(Y66:Z66) -> 1 | AH66: =AVERAGE(AA66:AB66) -> 0 | AI66: =AVERAGE(AC66:AD66) -> 0 | AJ66: =AVERAGE(AE66:AF66) -> 0 | AK66: 0 | AL66: 0 | AM66: 0 | AN66: 1 | AO66: 18 | AP66: 2 | AQ66: 1
A67: 186 | B67: Richard Lopez | C67: Lopez et al. | D67: Worcester Polytechnic Institute | E67: USA | F67: 2 | G67: 4 | H67: 1 | I67: 0 | J67: 0 | K67: 1 | L67: 1 | M67: 1 | N67: 0 | O67: 0 | P67: 0 | Q67: 0 | R67: 0 | S67: 1 | T67: 1 | U67: 1 | V67: 0 | W67: 0 | X67: 0 | Y67: 0 | Z67: 0 | AA67: 1 | AB67: 1 | AC67: 1 | AD67: 0 | AE67: 0 | AF67: 0 | AG67: =AVERAGE(Y67:Z67) -> 0 | AH67: =AVERAGE(AA67:AB67) -> 1 | AI67: =AVERAGE(AC67:AD67) -> 0.5 | AJ67: =AVERAGE(AE67:AF67) -> 0 | AK67: 0 | AL67: 0 | AM67: 0 | AN67: 1 | AO67: 19 | AP67: 1 | AQ67: 1
A68: 187 | B68: Richard Lopez | C68: Lopez et al. | D68: Worcester Polytechnic Institute | E68: USA | F68: 1 | G68: 2 | H68: 1 | I68: 0 | J68: 1 | K68: 1 | L68: 1 | M68: 0 | N68: 1 | O68: 0 | P68: 0 | Q68: 0 | R68: 1 | S68: 1 | T68: 1 | U68: 0 | V68: 1 | W68: 0 | X68: 0 | Y68: 0 | Z68: 1 | AA68: 1 | AB68: 1 | AC68: 0 | AD68: 1 | AE68: 0 | AF68: 0 | AG68: =AVERAGE(Y68:Z68) -> 0.5 | AH68: =AVERAGE(AA68:AB68) -> 1 | AI68: =AVERAGE(AC68:AD68) -> 0.5 | AJ68: =AVERAGE(AE68:AF68) -> 0 | AK68: 0 | AL68: 0 | AM68: 0 | AN68: 2 | AO68: 19 | AP68: 1 | AQ68: 1
A69: 188 | B69: Richard Lopez | C69: Lopez et al. | D69: Worcester Polytechnic Institute | E69: USA | F69: 2 | G69: 4 | H69: 2 | I69: 0 | J69: 0 | K69: 1 | L69: 0 | M69: 0 | N69: 1 | O69: 0 | P69: 1 | Q69: 0 | R69: 0 | S69: 1 | T69: 0 | U69: 0 | V69: 1 | W69: 0 | X69: 1 | Y69: 0 | Z69: 0 | AA69: 1 | AB69: 0 | AC69: 0 | AD69: 1 | AE69: 0 | AF69: 1 | AG69: =AVERAGE(Y69:Z69) -> 0 | AH69: =AVERAGE(AA69:AB69) -> 0.5 | AI69: =AVERAGE(AC69:AD69) -> 0.5 | AJ69: =AVERAGE(AE69:AF69) -> 0.5 | AK69: 0 | AL69: 0 | AM69: 0 | AN69: 1 | AO69: 20 | AP69: 2 | AQ69: 1
A70: 189 | B70: Richard Lopez | C70: Lopez et al. | D70: Worcester Polytechnic Institute | E70: USA | F70: 1 | G70: 1 | H70: 2 | I70: 0 | J70: 0 | K70: 0 | L70: 0 | M70: 0 | N70: 1 | O70: 0 | P70: 0 | Q70: 0 | R70: 0 | S70: 0 | T70: 0 | U70: 0 | V70: 1 | W70: 0 | X70: 0 | Y70: 0 | Z70: 0 | AA70: 0 | AB70: 0 | AC70: 0 | AD70: 1 | AE70: 0 | AF70: 0 | AG70: =AVERAGE(Y70:Z70) -> 0 | AH70: =AVERAGE(AA70:AB70) -> 0 | AI70: =AVERAGE(AC70:AD70) -> 0.5 | AJ70: =AVERAGE(AE70:AF70) -> 0 | AK70: 0 | AL70: 0 | AM70: 0 | AN70: 2 | AO70: 18 | AP70: 2 | AQ70: 1
...

Sheet summarystats
A1: Correct responses
B2: Concentration | C2: Suppression
A3: High time pressure | B3: =AVERAGEIF(testdata!$F$2:$F$89, "Concentration", testdata!AH2:AH89) -> #DIV/0! | C3: =AVERAGEIF(testdata!$F$2:$F$89, "Suppression", testdata!AH2:AH89) -> #DIV/0!
A4: Low time pressure | B4: =AVERAGEIF(testdata!$F$2:$F$89, "Concentration", testdata!AG2:AG89) -> #DIV/0! | C4: =AVERAGEIF(testdata!$F$2:$F$89, "Suppression", testdata!AG2:AG89) -> #DIV/0!
A6: RT responses
B7: Concentration | C7: Suppression
A8: High time pressure | B8: =AVERAGEIF(testdata!$F$2:$F$89, "Concentration", testdata!AJ2:AJ89) -> #DIV/0! | C8: =AVERAGEIF(testdata!$F$2:$F$89, "Suppression", testdata!AJ2:AJ89) -> #DIV/0!
A9: Low time pressure | B9: =AVERAGEIF(testdata!$F$2:$F$89, "Concentration", testdata!AI2:AI89) -> #DIV/0! | C9: =AVERAGEIF(testdata!$F$2:$F$89, "Suppression", testdata!AI2:AI89) -> #DIV/0!
